File: Lab2/LabData/Tension/Test Run 3 10-6-2016 2 44 27 PM/DAQ- Crosshead, … - (Timed).csv
"File Path: F:\Test Run 3 10-6-2016 2 44 27 PM\DAQ- Crosshead, … - (Timed).csv
Test: MTS EM Tension (Extensometer) 28
Test Run: Test Run 3
Date: 10/6/2016 2:18:46 PM

"
"Crosshead ","Load ","Time ","Extensometer "
"mm","N","sec","mm"
"0.00256101975537604","94.7472915649414","0.11599999666214","0.000567105644222465"
"0.00750438357499661","205.763275146484","0.316000014543533","0.00197056579054333"
"0.0125668648252031","316.481994628906","0.515999972820282","0.00341376744472655"
"0.0176293451659149","427.125061035156","0.716000020503998","0.00485702503283392"
"0.022691827325616","529.489135742188","0.916000008583069","0.0062183116824599"
"0.0277543094853172","629.697448730469","1.11600005626678","0.00757281713958946"
"0.0328167916450184","726.447448730469","1.31599998474121","0.00878834998729872"
"0.0378197146346793","819.449584960938","1.51600003242493","0.0100207189461798"
"0.0429417523264419","911.095886230469","1.71599996089935","0.0111780400402495"
"0.047944671678124","998.513977050781","1.91600000858307","0.0123465733850026"
"0.0530071556568146","1084.16003417969","2.1159999370575","0.0134639576572226"
"0.0581291933485772","1168.64404296875","2.31599998474121","0.0145335379784228"
"0.0631321163382381","1249.76928710938","2.51600003242493","0.0156140540639171"
"0.0682541576679796","1328.73315429688","2.71600008010864","0.0166780428116908"
"0.0733166380086914","1404.15795898438","2.91599988937378","0.0176641642610775"
"0.0783195573603734","1478.77685546875","3.1159999370575","0.0186414054041961"
"0.0834415986901149","1551.68908691406","3.31599998474121","0.0196120145119494"
"0.0885040863067843","1620.8642578125","3.51600003242493","0.0206059321499197"
"0.0935665593715385","1690.62158203125","3.71600008010864","0.0214164429053199"
"0.0986290397122502","1758.85754394531","3.91599988937378","0.0223065926547861"
"0.10369152732892","1824.57849121094","4.11600017547607","0.0232919737754855"
"0.108754007669631","1889.52124023438","4.31599998474121","0.0241278448811499"
"0.113816488010343","1951.61560058594","4.51599979400635","0.0248134638241027"
"0.118878968351055","2013.68359375","4.71600008010864","0.0257992069236934"
"0.123941455967724","2075.48364257813","4.91599988937378","0.0264560731011443"
"0.129003921756521","2135.12817382813","5.11600017547607","0.0272748202405637"
"0.134125963086262","2193.42797851563","5.31599998474121","0.0280193635262549"
"0.139188457978889","2251.04418945313","5.51599979400635","0.0288345181616023"
"0.144250923767686","2307.31909179688","5.71600008010864","0.0295056270260829"
"0.149313418660313","2362.64721679688","5.91599988937378","0.0302241605822928"
"0.154375899001025","2416.56298828125","6.11600017547607","0.0308988710457925"
"0.159378818352707","2468.11303710938","6.31599998474121","0.0316577752528246"
"0.164500859682448","2519.84155273438","6.51599979400635","0.0322709165629931"
"0.16956334002316","2571.70849609375","6.71600008010864","0.0329435824824031"
"0.174625820363872","2622.54858398438","6.91599988937378","0.0336324155796319"
"0.179747861693613","2672.30688476563","7.11600017547607","0.0342746752721723"
"0.184750781045295","2721.06591796875","7.31599998474121","0.0349107103829738"
"0.189872822375037","2770.49072265625","7.51599979400635","0.0355840420525055"
"0.194935302715749","2818.28344726563","7.71600008010864","0.0361962738679722"
"0.199938222067431","2864.83813476563","7.91599988937378","0.0368461478501558"
"0.205000702408142","2911.51391601563","8.11600017547607","0.0373427392332815"
"0.210063182748854","2957.42529296875","8.31599998474121","0.0379201956093311"
"0.215185224078596","3002.64819335938","8.51599979400635","0.0385363891837187"
"0.220307265408337","3046.31005859375","8.71599960327148","0.0391067223972641"
"0.225310184760019","3088.07397460938","8.91600036621094","0.0395960523746908"
"0.230432226089761","3129.78881835938","9.11600017547607","0.0401910401706118"
"0.235494706430472","3172.6552734375","9.31599998474121","0.0407207735406701"
"0.240557186771184","3213.16430664063","9.51599979400635","0.0412724002671894"
"0.245619681663811","3256.251953125","9.71599960327148","0.0417595583712682"
"0.250682147452608","3298.1826171875","9.91600036621094","0.0423423043685034"
"0.255744642345235","3340.91967773438","10.1160001754761","0.042882704292424"
"0.260866683674976","3384.0849609375","10.3159999847412","0.0434186113125179"
"0.265929149463773","3425.44775390625","10.5159997940063","0.0439409486716613"
"0.270991615252569","3468.36279296875","10.7159996032715","0.0445583827968221"
"0.276054110145196","3510.43041992188","10.9160003662109","0.0450251318397932"
"0.281116605037823","3552.4169921875","11.1160001754761","0.0456531743111555"
"0.286238646367565","3594.55297851563","11.3159999847412","0.0461478266515769"
"0.291241565719247","3637.08251953125","11.5159997940063","0.0467071804450825"
"0.296304060611874","3678.8466796875","11.7159996032715","0.0472784377052449"
"0.301426072837785","3721.9716796875","11.9160003662109","0.0478995898447465"
"0.306488567730412","3763.41967773438","12.1160001754761","0.0483122603327502"
"0.311610609060153","3805.84741210938","12.3159999847412","0.0489270933030639"
"0.316613528411835","3848.3642578125","12.5159997940063","0.0493382540298626"
"0.321676023304462","3890.1796875","12.7159996032715","0.0498972804052755"
"0.326798064634204","3932.58642578125","12.9160003662109","0.0505596326547675"
"0.33186050131917","3974.34057617188","13.1160001754761","0.0509878809680231"
"0.336922996211797","4016.20654296875","13.3159999847412","0.0516428808623459"
"0.341985491104424","4057.91845703125","13.5159997940063","0.0520955909451004"
"0.347107532434165","4099.57080078125","13.7159996032715","0.0526290932612028"
"0.352170027326792","4142.20556640625","13.9160003662109","0.0532426856807433"
"0.357232493115589","4182.4296875","14.1160001754761","0.053662974096369"
"0.362235383363441","4222.4853515625","14.3159999847412","0.0541726767551154"
"0.367357453797013","4263.7900390625","14.5159997940063","0.0547627714695409"
"0.372419919585809","4303.72705078125","14.7159996032715","0.0552891942788847"
"0.377541960915551","4343.8623046875","14.9160003662109","0.0557454659428913"
"0.382604455808178","4384.39013671875","15.1160001754761","0.0562235254619736"
"0.387666950700805","4424.22509765625","15.3159999847412","0.0567395800317172"
"0.392788962926716","4464.02197265625","15.5159997940063","0.0573816578253172"
"0.397791882278398","4503.92724609375","15.7159996032715","0.05782055814052"
"0.402854377171025","4543.14013671875","15.9160003662109","0.0582969551032875"
"0.407916842959821","4582.375","16.1159992218018","0.0588899420108646"
"0.413038913393393","4620.23046875","16.3159999847412","0.0593903350818437"
"0.418160954723135","4658.02880859375","16.5160007476807","0.0597766193095595"
"0.423223420511931","4696.5732421875","16.7159996032715","0.0602057443757076"
"0.428226339863613","4734.46728515625","16.9160003662109","0.060789145209128"
"0.433348381193355","4772.6923828125","17.1159992218018","0.0613055308349431"
"0.438410846982151","4809.53125","17.3159999847412","0.0617287732893601"
"0.443473341874778","4846.9833984375","17.5160007476807","0.0622783918515779"
"0.448535836767405","4886.1015625","17.7159996032715","0.0627872432232834"
"0.453538756119087","4923.4423828125","17.9160003662109","0.06322829722194"
"0.458720343885943","4962.93603515625","18.1159992218018","0.0637622360954992"
"0.46378280967474","5001.58837890625","18.3159999847412","0.064301559177693"
"0.468845304567367","5038.9931640625","18.5160007476807","0.064781736000441"
"0.473967345897108","5078.20703125","18.7159996032715","0.0653028764645569"
"0.47897026524879","5116.31396484375","18.9160003662109","0.0657819909974933"
"0.484092306578532","5153.64990234375","19.1159992218018","0.0663412065478042"
"0.489154772367328","5192.53125","19.3159999847412","0.0667849308229052"
"0.494157720822841","5228.57421875","19.5160007476807","0.0673130343784578"
"0.499279762152582","5267.09716796875","19.7159996032715","0.0678233191138133"
"0.504401803482324","5306.2705078125","19.9160003662109","0.0683137186570093"
"0.509404693730176","5343.89990234375","20.1159992218018","0.0688165309838951"
"0.514526735059917","5382.62744140625","20.3159999847412","0.0692846660967916"
"0.519589229952544","5420.4296875","20.5160007476807","0.0699303272995166"
"0.524651724845171","5459.47802734375","20.7159996032715","0.0703460100339726"
"0.529714219737798","5498.5439453125","20.9160003662109","0.0709132800693624"
"0.534776714630425","5537.09326171875","21.1159992218018","0.071408343501389"
"0.539839151315391","5575.0771484375","21.3159999847412","0.0719026211299933"
"0.544901646208018","5614.9892578125","21.5160007476807","0.0725309873814695"
"0.55002368753776","5652.279296875","21.7159996032715","0.0730275496607646"
"0.555086124222726","5692.9140625","21.9160003662109","0.0735630965209566"
"0.560148677323014","5731.1611328125","22.1159992218018","0.0740818868507631"
"0.56521111400798","5769.50439453125","22.3159999847412","0.0746613441151567"
"0.570273550692946","5809.59619140625","22.5160007476807","0.0751699990360066"
"0.575336103793234","5848.2119140625","22.7159996032715","0.0757010711822659"
"0.5803985404782","5887.77587890625","22.9160003662109","0.0762724666856229"
"0.585520640015602","5926.97900390625","23.1159992218018","0.0768464597058482"
"0.590583076700568","5966.59375","23.3159999847412","0.0773720967117697"
"0.595705176237971","6007.25634765625","23.5160007476807","0.0779465844971128"
"0.600708066485822","6045.96875","23.7159996032715","0.0784765361458994"
"0.605770503170788","6086.00830078125","23.9160003662109","0.0791353450040333"
"0.610892602708191","6126.26904296875","24.1159992218018","0.0796499516582116"
"0.615955039393157","6165.50048828125","24.3159999847412","0.0801927963038906"
"0.621077138930559","6206.06298828125","24.5160007476807","0.0808682598290034"
"0.626080029178411","6245.81103515625","24.7159996032715","0.0814051818451844"
"0.631142524071038","6285.62158203125","24.9160003662109","0.0819794440758415"
"0.636264565400779","6325.5712890625","25.1159992218018","0.0826021496322937"
"0.641327002085745","6365.1865234375","25.3159999847412","0.0833133381092921"
"0.646329950541258","6405.31787109375","25.5160007476807","0.0837832121760584"
"0.651451991870999","6445.73779296875","25.7159996032715","0.0845101239974611"
"0.656514486763626","6485.9619140625","25.9160003662109","0.0850038268254139"
"0.661636469885707","6525.35986328125","26.1159992218018","0.0856784099596553"
"0.666698964778334","6565.3134765625","26.3159999847412","0.0861933658597991"
"0.671761459670961","6604.22705078125","26.5160007476807","0.0869432551553473"
"0.676823896355927","6644.9814453125","26.7159996032715","0.0875234763952903"
"0.681886449456215","6683.71728515625","26.9160003662109","0.0882111198734492"
"0.686948886141181","6723.5615234375","27.1159992218018","0.0888963186298497"
"0.692011381033808","6763.90771484375","27.3159999847412","0.0895427510840818"
"0.697073875926435","6802.63916015625","27.5160007476807","0.0903261170606129"
"0.702195859048516","6843.263671875","27.7159996032715","0.0909472437342629"
"0.707258412148803","6882.48291015625","27.9160003662109","0.0915580167202279"
"0.71232084883377","6920.14990234375","28.1159992218018","0.0922328254091553"
"0.717442948371172","6960.8916015625","28.3159999847412","0.0929969901335426"
"0.722505385056138","7000.31591796875","28.5160007476807","0.0937119693844579"
"0.727567879948765","7038.74169921875","28.7159996032715","0.0944322309806012"
"0.732630374841392","7078.0830078125","28.9160003662109","0.0951812835410237"
"0.737633265089244","7116.6044921875","29.1159992218018","0.0959222452365793"
"0.742755306418985","7155.7421875","29.3159999847412","0.0965549916145392"
"0.747817801311612","7195.49072265625","29.5160007476807","0.0973910791799426"
"0.752939842641354","7233.2177734375","29.7159996032715","0.0982114434009418"
"0.758002337533981","7272.3173828125","29.9160003662109","0.0990193657344207"
"0.763064774218947","7310.205078125","30.1159992218018","0.0997869356069714"
"0.768127269111574","7348.7919921875","30.3159999847412","0.100600802397821"
"0.773189764004201","7387.78125","30.5160007476807","0.101464400358964"
"0.778252258896828","7424.18896484375","30.7159996032715","0.102327685453929"
"0.783314695581794","7463.05419921875","30.9160003662109","0.103283062344417"
"0.788436795119196","7501.185546875","31.1159992218018","0.104107850347646"
"0.793499231804162","7538.7236328125","31.3159999847412","0.104938757431228"
"0.798621273133904","7576.32470703125","31.5160007476807","0.105925762909465"
"0.803624221589416","7612.75244140625","31.7159996032715","0.106872976175509"
"0.808686658274382","7649.05419921875","31.9160003662109","0.107858562842011"
"0.813808757811785","7687.29931640625","32.1160011291504","0.108756539702881"
"0.818871194496751","7723.4541015625","32.3160018920898","0.109823951788712"
"0.823933689389378","7758.84716796875","32.515998840332","0.110740606032778"
"0.828996184282005","7794.22265625","32.7159996032715","0.111753921373747"
"0.834058620966971","7830.36865234375","32.9160003662109","0.112784218799789"
"0.839180720504373","7866.421875","33.1160011291504","0.113808375317603"
"0.844183610752225","7901.18994140625","33.3160018920898","0.114917311293539"
"0.849246105644852","7936.6826171875","33.515998840332","0.115998132969253"
"0.854368146974593","7971.73193359375","33.7159996032715","0.117125724500511"
"0.859430583659559","8005.3076171875","33.9160003662109","0.118206917250063"
"0.864552683196962","8040.70703125","34.1160011291504","0.119415555673186"
"0.869615119881928","8075.00390625","34.3160018920898","0.120608419820201"
"0.874677614774555","8108.27978515625","34.515998840332","0.121755467262119"
"0.879799656104296","8143.16552734375","34.7159996032715","0.123033940326422"
"0.884802604559809","8175.66748046875","34.9160003662109","0.124202444567345"
"0.889865041244775","8208.1142578125","35.1160011291504","0.125447710161097"
"0.894987082574517","8242.5576171875","35.3160018920898","0.126750470371917"
"0.899990031030029","8274.8310546875","35.515998840332","0.128080413560383"
"0.905171618796885","8308.2802734375","35.7159996032715","0.129444728372619"
"0.910174567252398","8339.5166015625","35.9160003662109","0.130813117721118"
"0.915237003937364","8371.09765625","36.1160011291504","0.132175104226917"
"0.920359103474766","8403.1865234375","36.3160018920898","0.133608584292233"
"0.925421540159732","8434.3857421875","36.515998840332","0.135076319565997"
"0.930483976844698","8465.318359375","36.7159996032715","0.136560513055883"
"0.935486983507872","8495.974609375","36.9160003662109","0.138070070534013"
"0.940549420192838","8525.4873046875","37.1160011291504","0.139673240482807"
"0.945731066167355","8556.8525390625","37.3160018920898","0.141253738547675"
"0.950793502852321","8585.87890625","37.515998840332","0.142748962389305"
"0.955796393100172","8614.2900390625","37.7159996032715","0.144414778333157"
"0.960918492637575","8644.4375","37.9160003662109","0.146016827784479"
"0.965980929322541","8672.103515625","38.1160011291504","0.147682076203637"
"0.971103028859943","8700.5908203125","38.3160018920898","0.149371291627176"
"0.976105919107795","8729.2353515625","38.515998840332","0.151153581100516"
"0.981168355792761","8755.9228515625","38.7159996032715","0.152931301272474"
"0.986290397122502","8783.5068359375","38.9160003662109","0.154799869051203"
"0.99135295022279","8811.3837890625","39.1160011291504","0.156583089847118"
"0.996474991552532","8837.4833984375","39.3160018920898","0.158474387717433"
"1.0015374282375","8863.580078125","39.515998840332","0.160437120939605"
"1.00659986492246","8888.328125","39.7159996032715","0.162281867233105"
"1.01166241802275","8913.9384765625","39.9160003662109","0.164262470207177"
"1.01678445935249","8938.380859375","40.1160011291504","0.166381039889529"
"1.02178740780801","8961.9697265625","40.3160018920898","0.168406841112301"
"1.02684984449297","8986.87890625","40.515998840332","0.170511746546254"
"1.03197188582271","9009.50390625","40.7159996032715","0.172668704180978"
"1.037034438923","9032.4658203125","40.9160003662109","0.174969565705396"
"1.04215648025274","9054.7490234375","41.1160011291504","0.177162030013278"
"1.04721891693771","9074.3154296875","41.3160018920898","0.179492883034982"
"1.05228135362267","9095.814453125","41.515998840332","0.181818671990186"
"1.05734379030764","9116.591796875","41.7159996032715","0.184222517418675"
"1.06240634340793","9135.8955078125","41.9160003662109","0.186783334356733"
"1.06752838473767","9155.69140625","42.1160011291504","0.18922722665593"
"1.07259082142264","9173.0478515625","42.3160018920898","0.191827479284257"
"1.0776532581076","9190.48046875","42.515998840332","0.194531108718365"
"1.08277529943734","9208.044921875","42.7159996032715","0.197395202121697"
"1.08777836430818","9222.30078125","42.9160003662109","0.200065362150781"
"1.0929002892226","9236.9609375","43.1160011291504","0.20299524476286"
"1.09796284232289","9251.23828125","43.3160018920898","0.205952805117704"
"1.10302527900785","9262.8671875","43.515998840332","0.208946992643178"
"1.10814743675292","9273.8974609375","43.7159996032715","0.212229322642088"
"1.11320987343788","9283.439453125","43.9160003662109","0.215377178392373"
"1.11827231012285","9291.5712890625","44.1160011291504","0.218688845052384"
"1.12339435145259","9298.0732421875","44.3160018920898","0.222159753320739"
"1.12845678813756","9302.140625","44.515998840332","0.225619194679894"
"1.13345973659307","9304.787109375","44.7159996032715","0.229311408475041"
"1.13858177792281","9306.8759765625","44.9160003662109","0.232991063967347"
"1.14364421460778","9306.1162109375","45.1160011291504","0.236773252254352"
"1.14876625593752","9305.0576171875","45.3160018920898","0.240635839872994"
"1.15382869262248","9301.798828125","45.515998840332","0.244648079387844"
"1.15895085036755","9298.197265625","45.7159996032715","0.248770724283531"
"1.16401328705251","9294.845703125","45.9160003662109","0.252874655416235"
"1.16907572373748","9289.5859375","46.1160011291504","0.257032079389319"
"1.17419776506722","9284.3935546875","46.3160018920898","0.261165085248649"
"1.17920071352273","9279.54296875","46.515998840332","0.265407928964123"
"1.18426326662302","9273.7138671875","46.7159996032715","0.269554206170142"
"1.18944479618222","9268.8076171875","46.9160003662109","0.27378523373045"
"1.1945073492825","9263.7275390625","47.1160011291504","0.278050632914528"
"1.19956978596747","9257.3720703125","47.3160018920898","0.2823596005328"
"1.20469171088189","9252.7421875","47.515998840332","0.286591122858226"
"1.20969477575272","9246.427734375","47.7159996032715","0.290931639028713"
"1.21481681708246","9240.4775390625","47.9160003662109","0.295296078547835"
"1.21987925376743","9235.0576171875","48.1160011291504","0.299538834951818"
"1.22488220222294","9229.3984375","48.3160018920898","0.303824985167012"
"1.23000424355268","9224.185546875","48.515998840332","0.308122049318627"
"1.23512628488243","9219.115234375","48.7159996032715","0.312537013087422"
"1.24018872156739","9212.88671875","48.9160003662109","0.316951016429812"
"1.24531076289713","9207.6015625","49.1160011291504","0.321352010359988"
"1.2503731995821","9200.173828125","49.3160018920898","0.325723231071606"
"1.25549535732716","9194.626953125","49.515998840332","0.330072740325704"
"1.26055779401213","9187.92578125","49.7159996032715","0.334554759319872"
"1.2656202306971","9181.0009765625","49.9160003662109","0.338906684191898"
"1.27068266738206","9174.4462890625","50.1160011291504","0.343365507433191"
"1.2758047087118","9167.0625","50.3160018920898","0.3478278813418"
"1.28086726181209","9158.6826171875","50.515998840332","0.352217408362776"
"1.28598930314183","9152.0595703125","50.7159996032715","0.356803328031674"
"1.2910517398268","9142.8134765625","50.9160003662109","0.36130371154286"
"1.29611429292709","9134.2587890625","51.1160011291504","0.365848216461018"
"1.30123621784151","9126.599609375","51.3160018920898","0.37032229010947"
"1.30623928271234","9116.400390625","51.515998840332","0.374881317839026"
"1.31136132404208","9107.990234375","51.7159996032715","0.379384349798784"
"1.31642376072705","9097.677734375","51.9160003662109","0.38391406997107"
"1.32148619741201","9088.1416015625","52.1160011291504","0.388496177038178"
"1.32666784338653","9078.966796875","52.3160018920898","0.393075781175867"
"1.33167079184204","9068.205078125","52.515998840332","0.397690542740747"
"1.33673322852701","9058.5322265625","52.7159996032715","0.402145902626216"
"1.34185526985675","9048.2373046875","52.9160003662109","0.406754988944158"
"1.34691770654172","9037.1767578125","53.1160011291504","0.411275686929002"
"1.35203986428678","9027.5908203125","53.3160018920898","0.415991875343025"
"1.35710230097175","9016.4912109375","53.515998840332","0.420626456616446"
"1.36216473765671","9005.6337890625","53.7159996032715","0.425171194365248"
"1.36734638363123","8993.9765625","53.9160003662109","0.429893581895158"
"1.3724088203162","8982.22265625","54.1160011291504","0.434477493399754"
"1.37741176877171","8970.28515625","54.3160018920898","0.439046445535496"
"1.38253381010145","8959.859375","54.515998840332","0.443785742390901"
"1.38759624678642","8947.5478515625","54.7159996032715","0.448364298790693"
"1.39271828811616","8936.6650390625","54.9160003662109","0.453107699286193"
"1.39778072480112","8924.728515625","55.1160011291504","0.457704736618325"
"1.40284327790141","8911.8955078125","55.3160018920898","0.462329422589391"
"1.40796531923115","8900.6640625","55.515998840332","0.467011326691136"
"1.41302775591612","8888.44140625","55.7159996032715","0.471656385343522"
"1.41809030901641","8875.6728515625","55.9160003662109","0.476340006571263"
"1.42315286211669","8864.447265625","56.1160011291504","0.481006398331374"
"1.42821529880166","8851.345703125","56.3160018920898","0.485632248455659"
"1.43339682836086","8840.76171875","56.515998840332","0.490358914248645"
"1.43845926504582","8827.13671875","56.7159996032715","0.495102838613093"
"1.44352181814611","8815.12890625","56.9160003662109","0.499816436786205"
"1.44864385947585","8803.6552734375","57.1160011291504","0.504546333104372"
"1.45370641257614","8790.548828125","57.3160018920898","0.509281177073717"
"1.45882833749056","8777.8232421875","57.515998840332","0.514059385750443"
"1.46383128594607","8765.5927734375","57.7159996032715","0.518832530360669"
"1.46889372263104","8751.966796875","57.9160003662109","0.523555499967188"
"1.4740158803761","8740.0615234375","58.1160011291504","0.528260308783501"
"1.47913792170584","8727.6953125","58.3160018920898","0.533152022399008"
"1.48420035839081","8714.546875","58.515998840332","0.537900836206973"
"1.48932239972055","8701.4697265625","58.7159996032715","0.542747380677611"
"1.49438483640552","8688.0634765625","58.9160003662109","0.547484029084444"
"1.4994473895058","8675.583984375","59.1160011291504","0.552220735698938"
"1.50456943083555","8662.498046875","59.3160018920898","0.556959654204547"
"1.50957226287574","8649.748046875","59.515998840332","0.561818887945265"
"1.51469430420548","8637.2978515625","59.7159996032715","0.566578644793481"
"1.51975674089044","8624.603515625","59.9160003662109","0.571287702769041"
"1.52487889863551","8611.7890625","60.1160011291504","0.576162245124578"
"1.52994133532047","8598.6865234375","60.3160018920898","0.581050233449787"
"1.53500377200544","8585.107421875","60.515998840332","0.585991481784731"
"1.54012581333518","8572.421875","60.7159996032715","0.590702285990119"
"1.54518825002015","8559.9541015625","60.9160003662109","0.595616642385721"
"1.55031040776521","8545.9111328125","61.1160011291504","0.600589963141829"
"1.55537284445018","8532.8232421875","61.3160018920898","0.605468288995326"
"1.56043528113514","8519.630859375","61.515998840332","0.610281422268599"
"1.56555732246488","8506.3994140625","61.7159996032715","0.61523646581918"
"1.57067948020995","8493.7939453125","61.9160003662109","0.620205071754754"
"1.57568242866546","8479.357421875","62.1160011291504","0.625030661467463"
"1.58074486535043","8466.7890625","62.3160018920898","0.629918824415654"
"1.58586679026484","8453.9208984375","62.515998840332","0.634841504506767"
"1.59092934336513","8439.73828125","62.7159996032715","0.639609526842833"
"1.59605138469487","8426.9921875","62.9160003662109","0.644570623990148"
"1.60105433315039","8413.7666015625","63.1160011291504","0.64959324663505"
"1.60617637448013","8400.091796875","63.3160018920898","0.654411502182484"
"1.61129841580987","8387.962890625","63.515998840332","0.659306184388697"
"1.61630124785006","8373.6005859375","63.7159996032715","0.664228457026184"
"1.62136380095035","8360.7744140625","63.9160003662109","0.669186294544488"
"1.62648584228009","8347.640625","64.1159973144531","0.674236740451306"
"1.63154827896506","8333.712890625","64.3160018920898","0.679153657983989"
"1.6366703202948","8321.4560546875","64.515998840332","0.684154743794352"
"1.64173275697976","8307.267578125","64.7160034179688","0.689236505422741"
"1.64685491472483","8293.2060546875","64.9160003662109","0.694205868057907"
"1.65197695605457","8279.828125","65.1159973144531","0.699261086992919"
"1.65697978809476","8265.9091796875","65.3160018920898","0.704263802617788"
"1.6621018294245","8252.3486328125","65.515998840332","0.709332816768438"
"1.66716438252479","8239.69921875","65.7160034179688","0.714362889993936"
"1.67222681920975","8224.353515625","65.9160003662109","0.719300587661564"
"1.6773488605395","8212.490234375","66.1159973144531","0.724463840015233"
"1.68241129722446","8198.1865234375","66.3160018920898","0.729471736121923"
"1.68747385032475","8183.626953125","66.515998840332","0.734586385078728"
"1.69259589165449","8170.296875","66.7160034179688","0.73967786738649"
"1.69765844475478","8155.9267578125","66.9160003662109","0.744652177672833"
"1.70272088143975","8143.11669921875","67.1159973144531","0.749683356843889"
"1.70784280635417","8129.39453125","67.3160018920898","0.75491180177778"
"1.71284575480968","8116.203125","67.515998840332","0.75992796337232"
"1.71796791255474","8102.099609375","67.7160034179688","0.765093602240086"
"1.72308995388448","8088.48291015625","67.9160003662109","0.770212849602103"
"1.72815239056945","8073.88720703125","68.1159973144531","0.775412132497877"
"1.73327443189919","8060.78564453125","68.3160018920898","0.780502043198794"
"1.73833686858416","8045.462890625","68.515998840332","0.785680778790265"
"1.74339942168444","8032.18603515625","68.7160034179688","0.790752994362265"
"1.74852146301419","8017.97216796875","68.9160003662109","0.796126725617796"
"1.75358389969915","8003.0654296875","69.1159973144531","0.801200745627284"
"1.75864633638412","7990.31298828125","69.3160018920898","0.8063122513704"
"1.76370877306908","7975.6787109375","69.515998840332","0.81147369928658"
"1.76883093081415","7961.41064453125","69.7160034179688","0.816691550426185"
"1.77395297214389","7947.79296875","69.9160003662109","0.821901019662619"
"1.77895580418408","7932.09765625","70.1159973144531","0.827126030344516"
"1.78407784551382","7919.138671875","70.3160018920898","0.832297722809017"
"1.78914039861411","7904.75341796875","70.515998840332","0.837512197904289"
"1.79420283529907","7889.62548828125","70.7160034179688","0.842667941469699"
"1.79932487662882","7876.5634765625","70.9160003662109","0.847887597046793"
"1.80438731331378","7861.5849609375","71.1159973144531","0.853101315442473"
"1.80944986641407","7847.95166015625","71.3160018920898","0.858326093293726"
"1.81463151238859","7833.57421875","71.515998840332","0.863665423821658"
"1.81963434442878","7818.63427734375","71.7160034179688","0.868893810547888"
"1.82475638575852","7803.60986328125","71.9160003662109","0.874191697221249"
"1.82981882244349","7789.95166015625","72.1159973144531","0.879473867826164"
"1.83488137554377","7774.37890625","72.3160018920898","0.88474596850574"
"1.84000341687351","7760.38623046875","72.515998840332","0.890106428414583"
"1.8450659699738","7745.1767578125","72.7160034179688","0.895386328920722"
"1.85018789488822","7730.7705078125","72.9160003662109","0.900716229807585"
"1.85530993621796","7717.13330078125","73.1159973144531","0.905946013517678"
"1.86037237290293","7701.66162109375","73.3160018920898","0.911343493498862"
"1.86537543777376","7686.2548828125","73.515998840332","0.916644581593573"
"1.87049747910351","7672.130859375","73.7160034179688","0.921919534448534"
"1.87555991578847","7656.56201171875","73.9160003662109","0.927249318920076"
"1.88068195711821","7642.01416015625","74.1159973144531","0.932553550228477"
"1.8857445102185","7626.814453125","74.3160018920898","0.937974255066365"
"1.89080694690347","7611.5869140625","74.515998840332","0.943285995163023"
"1.89592898823321","7597.03369140625","74.7160034179688","0.948638771660626"
"1.90099142491817","7581.216796875","74.9160003662109","0.954062910750508"
"1.90611346624792","7566.451171875","75.1159973144531","0.959386641625315"
"1.91111641470343","7551.3603515625","75.3160018920898","0.964726554229856"
"1.91617885138839","7536.826171875","75.515998840332","0.970085966400802"
"1.92136049736291","7521.9521484375","75.7160034179688","0.975562550593168"
"1.92642293404788","7505.79736328125","75.9160003662109","0.981110846623778"
"1.93148537073284","7490.2509765625","76.1159973144531","0.986320315860212"
"1.93666713312268","7475.18994140625","76.3160018920898","0.991875305771828"
"1.94166996516287","7459.48828125","76.515998840332","0.997227034531534"
"1.94679200649261","7442.5634765625","76.7160034179688","1.00264721550047"
"1.95185444317758","7428.26025390625","76.9160003662109","1.00805307738483"
"1.95691687986255","7411.05322265625","77.1159973144531","1.01340946275741"
"1.96197931654751","7396.6025390625","77.3160018920898","1.01885292679071"
"1.96710135787725","7380.55712890625","77.515998840332","1.02428381796926"
"1.97216402739286","7364.01904296875","77.7160034179688","1.02972879540175"
"1.97728606872261","7348.68017578125","77.9160003662109","1.03515258524567"
"1.98234850540757","7333.02099609375","78.1159973144531","1.04053597897291"
"1.98741094209254","7317.251953125","78.3160018920898","1.04606326203793"
"1.99253298342228","7301.17724609375","78.515998840332","1.05147704016417"
"1.99753604829311","7284.11962890625","78.7160034179688","1.05694017838687"
"2.00265785679221","7268.81201171875","78.9160003662109","1.06245581991971"
"2.00772052630782","7252.64013671875","79.1159973144531","1.06791988946497"
"2.01284233480692","7235.6064453125","79.3160018920898","1.07353506609797"
"2.0179646089673","7218.927734375","79.515998840332","1.07914081308991"
"2.02302704565227","7201.595703125","79.7160034179688","1.08461338095367"
"2.02808948233724","7185.25537109375","79.9160003662109","1.09011470340192"
"2.03321152366698","7169.1220703125","80.1159973144531","1.09564128797501"
"2.03827396035194","7151.34716796875","80.3160018920898","1.10113329719752"
"2.04333639703691","7134.625","80.515998840332","1.10671913716942"
"2.04839906655252","7117.85595703125","80.7160034179688","1.11218460369855"
"2.05352087505162","7100.79736328125","80.9160003662109","1.1176816187799"
"2.058643149212","7083.93017578125","81.1159973144531","1.12341227941215"
"2.06364598125219","7065.2001953125","81.3160018920898","1.12888566218317"
"2.06876802258193","7048.1669921875","81.515998840332","1.13443355076015"
"2.07383069209754","7031.3896484375","81.7160034179688","1.13996583968401"
"2.07889289595187","7013.056640625","81.9160003662109","1.14555598702282"
"2.08407454192638","6995.1025390625","82.1159973144531","1.15116429515183"
"2.08907737396657","6977.10302734375","82.3160018920898","1.15676131099463"
"2.09419941529632","6957.4990234375","82.515998840332","1.16242794319987"
"2.0993216894567","6937.6728515625","82.7160034179688","1.16806733421981"
"2.10438389331102","6886.4345703125","82.9160003662109","1.17466296069324"
"2.10962514393032","5702.951171875","83.1159973144531","1.21766654774547"
"2.11165030486882","-608.109008789063","83.1380004882813","1.20074616279453"