File: Lab2/LabData/Tension/Test Run 4 10-6-2016 2 44 52 PM/DAQ- Crosshead, … - (Timed).csv
"File Path: F:\Test Run 4 10-6-2016 2 44 52 PM\DAQ- Crosshead, … - (Timed).csv
Test: MTS EM Tension (Extensometer) 28
Test Run: Test Run 4
Date: 10/6/2016 2:28:06 PM

"
"Crosshead ","Load ","Time ","Extensometer "
"mm","N","sec","mm"
"0.00238234406424453","65.9082489013672","0.114000000059605","0.000591545415318251"
"0.0199521309696138","468.9794921875","0.814000010490417","0.0057683664635988"
"0.0376410389435478","847.171325683594","1.51400005817413","0.0105677418105188"
"0.0553299396415241","1204.24108886719","2.21399998664856","0.0154556400957517"
"0.0730188403395005","1542.25109863281","2.91400003433228","0.0198701927729417"
"0.0906481873244047","1865.60192871094","3.61400008201599","0.0242599398916354"
"0.108396656287368","2178.36767578125","4.31400012969971","0.0285083042399492"
"0.126204671687447","2242.16943359375","5.01399993896484","0.0399367927457206"
"0.144012708915398","2160.4169921875","5.71400022506714","0.0565859227208421"
"0.161761170602404","2127.6201171875","6.41400003433228","0.0717029397492297"
"0.17945007130038","2187.1201171875","7.11399984359741","0.0857402192195877"
"0.1972580794245","2234.56225585938","7.81400012969971","0.10012136772275"
"0.215066102100536","2274.03271484375","8.51399993896484","0.114693270006683"
"0.232874124776572","2296.283203125","9.21399974822998","0.129676380311139"
"0.250622601015493","2310.16870117188","9.91399955749512","0.14484410348814"
"0.268371048150584","2317.9482421875","10.6140003204346","0.160300041898154"
"0.286119524389505","2320.17358398438","11.3140001296997","0.175889232195914"
"0.303927547065541","2320.57568359375","12.0139999389648","0.192096413229592"
"0.321795145282522","2317.2900390625","12.71399974823","0.208530254894868"
"0.339543592417613","2315.82763671875","13.4139995574951","0.225125200813636"
"0.357351615093648","2312.73510742188","14.1140003204346","0.24169146490749"
"0.375040515791625","2307.27270507813","14.8140001296997","0.258509040577337"
"0.392908084904775","2310.17797851563","15.5139999389648","0.275170925306156"
"0.410656532039866","2310.43237304688","16.2140007019043","0.291756034130231"
"0.428464554715902","2312.07788085938","16.9139995574951","0.308396032778546"
"0.446213030954823","2308.60766601563","17.6140003204346","0.324913708027452"
"0.463961507193744","2306.33129882813","18.3139991760254","0.341466802638024"
"0.481709954328835","2306.57250976563","19.0139999389648","0.357923650881276"
"0.499518006108701","2303.36474609375","19.7140007019043","0.374711438780651"
"0.517385546118021","2304.54858398438","20.4139995574951","0.391475798096508"
"0.535074446815997","2305.20166015625","21.1140003204346","0.408206367865205"
"0.552882498595864","2304.49755859375","21.8139991760254","0.424876634497195"
"0.570630945730954","2302.39794921875","22.5139999389648","0.440787727711722"
"0.588438997510821","2300.04760742188","23.2140007019043","0.456814013887197"
"0.606246991083026","2300.75463867188","23.9139995574951","0.47315438860096"
"0.623995496425778","2302.89111328125","24.6140003204346","0.489511410705745"
"0.641803489997983","2299.77783203125","25.3139991760254","0.506004493217915"
"0.659551937133074","2291.90234375","26.0139999389648","0.522833724971861"
"0.67735998891294","2249.4169921875","26.7140007019043","0.541211746167392"
"0.695108436048031","2348.82397460938","27.4139995574951","0.554836529772729"
"0.712916429620236","2394.19311523438","28.1140003204346","0.56846474763006"
"0.730664934962988","2420.88330078125","28.8139991760254","0.582025037147105"
"0.748413382098079","2440.13305664063","29.5139999389648","0.595297780819237"
"0.766221375670284","2457.79638671875","30.2140007019043","0.608497473876923"
"0.783969881013036","2475.228515625","30.9139995574951","0.621867075096816"
"0.801837421022356","2491.06909179688","31.6140003204346","0.635161413811147"
"0.819526379927993","2505.74560546875","32.3139991760254","0.648315530270338"
"0.837334373500198","2520.78735351563","33.0139999389648","0.661333440802991"
"0.855142425280064","2534.54443359375","33.7140007019043","0.67462376318872"
"0.872890814207494","2550.369140625","34.4140014648438","0.687905121594667"
"0.89069886598736","2563.81640625","35.1139984130859","0.700941658578813"
"0.908447313122451","2577.0048828125","35.8139991760254","0.71363802999258"
"0.926255364902318","2590.1875","36.5139999389648","0.725937483366579"
"0.944003812037408","2603.15014648438","37.2140007019043","0.738643226213753"
"0.961811863817275","2616.56201171875","37.9140014648438","0.751458981540054"
"0.979560310952365","2629.98559570313","38.6139984130859","0.764254888053983"
"0.997368362732232","2643.0703125","39.3139991760254","0.777316105086356"
"1.01511680986732","2655.43823242188","40.0139999389648","0.790444668382406"
"1.03292474523187","2668.31494140625","40.7140007019043","0.803717586677521"
"1.05067319236696","2681.31323242188","41.4140014648438","0.816988234873861"
"1.06848136056215","2694.00415039063","42.1139984130859","0.830415810924023"
"1.08628929592669","2706.4716796875","42.8139991760254","0.84406667156145"
"1.10403774306178","2719.17700195313","43.5139999389648","0.85766549455002"
"1.12184579484165","2729.97143554688","44.2140007019043","0.871336203999817"
"1.13959435839206","2741.41625976563","44.9140014648438","0.884928333107382"
"1.15734280552715","2753.47631835938","45.6139984130859","0.898559810593724"
"1.1751507408917","2765.158203125","46.3139991760254","0.912392279133201"
"1.19295879267156","2777.20043945313","47.0139999389648","0.926069740671664"
"1.21070723980665","2787.18383789063","47.7140007019043","0.939722871407866"
"1.22845568694174","2798.849609375","48.4140014648438","0.953441369347274"
"1.24626373872161","2810.21508789063","49.1139984130859","0.967285363003612"
"1.2640121858567","2821.552734375","49.8139991760254","0.981171382591128"
"1.28182012122124","2832.20336914063","50.5139999389648","0.995141337625682"
"1.29962828941643","2842.81396484375","51.2140007019043","1.00896018557251"
"1.31737673655152","2853.2958984375","51.9140014648438","1.02286541368812"
"1.33512518368661","2863.46508789063","52.6139984130859","1.03662768378854"
"1.35293311905116","2873.11743164063","53.3139991760254","1.05062196962535"
"1.37074128724635","2884.08374023438","54.0139999389648","1.06462126132101"
"1.38848973438144","2893.52099609375","54.7140007019043","1.07855757232755"
"1.40629766974598","2904.63232421875","55.4140014648438","1.09240540768951"
"1.42404611688107","2912.96044921875","56.1139984130859","1.1064475402236"
"1.44185416866094","2922.86694335938","56.8139991760254","1.12042517866939"
"1.45960261579603","2932.23071289063","57.5139999389648","1.13445764873177"
"1.4774106675759","2941.91870117188","58.2140007019043","1.14851421676576"
"1.49521860294044","2951.28002929688","58.9140014648438","1.16256054025143"
"1.5129076782614","2960.68603515625","59.6139984130859","1.17649219464511"
"1.53071561362594","2969.80053710938","60.3139991760254","1.19054480455816"
"1.54852366540581","2979.07055664063","61.0139999389648","1.20462547056377"
"1.56633160077035","2988.32250976563","61.7140007019043","1.218635821715"
"1.58408004790545","2997.07690429688","62.4140014648438","1.23283616267145"
"1.60182861145586","3005.33227539063","63.1139984130859","1.24687445349991"
"1.6196365468204","3014.37719726563","63.8139991760254","1.26090389676392"
"1.63738499395549","3022.76782226563","64.5139999389648","1.27514242194593"
"1.65519304573536","3031.45629882813","65.213996887207","1.28920376300812"
"1.67300109751523","3039.52612304688","65.9140014648438","1.30336766596884"
"1.69074954465032","3047.23706054688","66.6139984130859","1.31731783039868"
"1.70849799178541","3055.05932617188","67.3140029907227","1.33150548208505"
"1.72630604356527","3063.82885742188","68.0139999389648","1.34566216729581"
"1.74411409534514","3071.3369140625","68.713996887207","1.35988451074809"
"1.76186254248023","3080.2587890625","69.4140014648438","1.37414317578077"
"1.7796705942601","3088.21069335938","70.1139984130859","1.3883487554267"
"1.79735943675041","3095.61962890625","70.8140029907227","1.40262383501977"
"1.81522697675973","3103.50170898438","71.5139999389648","1.41693488694727"
"1.83297554031014","3110.37817382813","72.213996887207","1.43126584589481"
"1.85078347567469","3118.6826171875","72.9140014648438","1.44564686343074"
"1.86859152745456","3125.40942382813","73.6139984130859","1.45992578472942"
"1.88628036994487","3133.18701171875","74.3140029907227","1.47413765080273"
"1.90408853814006","3139.76586914063","75.0139999389648","1.48850120604038"
"1.9218964735046","3148.0283203125","75.713996887207","1.50290364399552"
"1.93970452528447","3155.44067382813","76.4140014648438","1.517329714261"
"1.95745308883488","3161.70434570313","77.1139984130859","1.53163354843855"
"1.97520153596997","3169.14428710938","77.8140029907227","1.54595589265227"
"1.99294998310506","3175.45703125","78.5139999389648","1.56040256842971"
"2.01075803488493","3182.005859375","79.213996887207","1.57489371486008"
"2.02856585383415","3189.86376953125","79.9140014648438","1.5892923111096"
"2.04631453379989","3197.06713867188","80.6139984130859","1.60368718206882"
"2.06412235274911","3202.80932617188","81.3140029907227","1.61798624321818"
"2.0818707998842","3208.63818359375","82.0139999389648","1.63235189393163"
"2.09967908449471","3215.41479492188","82.713996887207","1.6469385009259"
"2.11742729879916","3221.94091796875","83.4140014648438","1.66147213894874"
"2.13523535057902","3228.23901367188","84.1139984130859","1.6760672442615"
"2.15298379771411","3234.84448242188","84.8140029907227","1.69053580611944"
"2.17079184949398","3240.39599609375","85.5139999389648","1.70506618451327"
"2.18854052945971","3246.3291015625","86.213996887207","1.71980389859527"
"2.20634834840894","3253.5859375","86.9140014648438","1.73435220494866"
"2.2241564001888","3259.2568359375","87.6139984130859","1.7489108722657"
"2.24190508015454","3265.30541992188","88.3140029907227","1.76332728005946"
"2.25971289910376","3270.50341796875","89.0139999389648","1.77787663415074"
"2.27746134623885","3276.50512695313","89.713996887207","1.79248861968517"
"2.29526916518807","3281.84130859375","90.4140014648438","1.80712970905006"
"2.31301784515381","3288.07739257813","91.1139984130859","1.82170607149601"
"2.3307662922889","3294.14697265625","91.8140029907227","1.83618732262403"
"2.3486337158829","3299.11791992188","92.5139999389648","1.85079465154558"
"2.36638239584863","3305.00341796875","93.213996887207","1.8654556479305"
"2.38413061015308","3310.45556640625","93.9140014648438","1.88010686542839"
"2.40193889476359","3315.57788085938","94.6139984130859","1.89475191291422"
"2.41968734189868","3320.7744140625","95.3140029907227","1.90952967386693"
"2.4374951608479","3325.51391601563","96.0139999389648","1.9242245471105"
"2.45530344545841","3330.53198242188","96.713996887207","1.93868181668222"
"2.4730518925935","3335.0302734375","97.4140014648438","1.95349659770727"
"2.49080010689795","3341.71533203125","98.1139984130859","1.96821591816843"
"2.50860839150846","3346.73852539063","98.8140029907227","1.98287819512188"
"2.52635660581291","3351.27392578125","99.5139999389648","1.99759821407497"
"2.54416465759277","3356.61376953125","100.213996887207","2.01238784939051"
"2.56197294220328","3361.01684570313","100.914001464844","2.02718283981085"
"2.57972115650773","3365.4794921875","101.613998413086","2.04196549020708"
"2.5975292082876","3370.85205078125","102.314002990723","2.05684453248978"
"2.61527765542269","3375.6279296875","103.013999938965","2.07164650782943"
"2.63308570720255","3380.25708007813","103.713996887207","2.08648387342691"
"2.65083438716829","3384.50610351563","104.414001464844","2.10140808485448"
"2.66858260147274","3389.29125976563","105.113998413086","2.11637676693499"
"2.68633104860783","3393.19091796875","105.814002990723","2.13122903369367"
"2.70419893786311","3398.98046875","106.513999938965","2.14601634070277"
"2.72194715216756","3402.6025390625","107.213996887207","2.16099852696061"
"2.73975520394742","3407.04443359375","107.914001464844","2.1758945658803"
"2.75750365108252","3411.17333984375","108.613998413086","2.19088699668646"
"2.77525209821761","3414.65112304688","109.314002990723","2.20578443259001"
"2.79311975464225","3420.65844726563","110.013999938965","2.2207850124687"
"2.81086820177734","3422.9365234375","110.713996887207","2.23568244837224"
"2.82867625355721","3428.92114257813","111.414001464844","2.25064181722701"
"2.84642446786165","3431.72509765625","112.113998413086","2.26552621461451"
"2.86417314782739","3436.08764648438","112.814002990723","2.2806623019278"
"2.88198119960725","3439.5625","113.513999938965","2.29559512808919"
"2.89978901855648","3444.4638671875","114.213996887207","2.31059640645981"
"2.91759730316699","3447.70703125","114.914001464844","2.32548895291984"
"2.9352861456573","3451.97973632813","115.613998413086","2.34068604186177"
"2.95309396460652","3455.50463867188","116.314002990723","2.3557529784739"
"2.97084264457226","3459.55688476563","117.013999938965","2.37072166055441"
"2.98865046352148","3463.35986328125","117.713996887207","2.38587125204504"
"3.00645851530135","3466.505859375","118.414001464844","2.40089860744774"
"3.02420719526708","3470.77685546875","119.113998413086","2.41594901308417"
"3.0420150142163","3473.86840820313","119.814002990723","2.43108021095395"
"3.05970408953726","3477.22216796875","120.513999938965","2.44618346914649"
"3.0775717459619","3481.21313476563","121.213996887207","2.46131652966142"
"3.09531996026635","3483.95971679688","121.914001464844","2.47643748298287"
"3.11312824487686","3488.8798828125","122.613998413086","2.49160849489272"
"3.13087645918131","3491.2734375","123.314002990723","2.50682700425386"
"3.1486249063164","3494.14965820313","124.013999938965","2.52208719030023"
"3.16643319092691","3498.04223632813","124.713996887207","2.53732060082257"
"3.18424100987613","3501.681640625","125.414001464844","2.55245040170848"
"3.202049061656","3505.00537109375","126.113998413086","2.56772874854505"
"3.21973790414631","3508.44946289063","126.814002990723","2.58273934014142"
"3.23754595592618","3511.11694335938","127.513999938965","2.5979948695749"
"3.25529463589191","3513.92456054688","128.214004516602","2.61335307732224"
"3.27316205948591","3517.43798828125","128.914001464844","2.62852618470788"
"3.29097011126578","3521.61889648438","129.613998413086","2.64376774430275"
"3.30865918658674","3524.31591796875","130.313995361328","2.65902862884104"
"3.32646700553596","3526.97290039063","131.014007568359","2.67440057359636"
"3.34421545267105","3529.62158203125","131.714004516602","2.68975272774696"
"3.36202327162027","3532.7958984375","132.414001464844","2.70499428734183"
"3.37983155623078","3535.13745117188","133.113998413086","2.72033317014575"
"3.39758000336587","3539.02124023438","133.813995361328","2.73558404296637"
"3.4153878223151","3541.42114257813","134.514007568359","2.75100953876972"
"3.43313650228083","3543.72998046875","135.214004516602","2.7664159424603"
"3.45094432123005","3546.41381835938","135.914001464844","2.78176111169159"
"3.46869300119579","3549.62915039063","136.613998413086","2.79711210168898"
"3.48656065762043","3552.67138671875","137.313995361328","2.81241675838828"
"3.5042492672801","3554.50952148438","138.014007568359","2.82789254561067"
"3.52205755189061","3556.91479492188","138.714004516602","2.84340954385698"
"3.5398059990257","3559.93530273438","139.414001464844","2.85892398096621"
"3.55761381797493","3562.48364257813","140.113998413086","2.87431292235851"
"3.57542210258543","3565.73657226563","140.813995361328","2.88963294588029"
"3.59317031688988","3567.89428710938","141.514007568359","2.9050933662802"
"3.61097836866975","3569.88354492188","142.214004516602","2.9206161852926"
"3.62872704863548","3572.69848632813","142.914001464844","2.93612200766802"
"3.64653486758471","3575.53588867188","143.613998413086","2.95141618698835"
"3.6642833147198","3577.4521484375","144.313995361328","2.96681351028383"
"3.68209136649966","3580.84765625","145.014007568359","2.98239383846521"
"3.69983981363475","3581.16040039063","145.714004516602","2.99791130237281"
"3.71758849360049","3584.5615234375","146.414001464844","3.01342899911106"
"3.73539631254971","3587.75610351563","147.113998413086","3.02901724353433"
"3.75320436432958","3590.13671875","147.813995361328","3.04434704594314"
"3.77101241610944","3591.552734375","148.514007568359","3.05989198386669"
"3.78876086324453","3594.11450195313","149.214004516602","3.07548115961254"
"3.8065689150244","3595.697265625","149.914001464844","3.09099745936692"
"3.82431712932885","3598.00537109375","150.613998413086","3.10653587803245"
"3.84206580929458","3600.74633789063","151.313995361328","3.12207359820604"
"3.85987386107445","3603.00854492188","152.014007568359","3.13759525306523"
"3.87768168002367","3604.79565429688","152.714004516602","3.1532768625766"
"3.8954303599894","3606.49975585938","153.414001464844","3.16900038160384"
"3.91317857429385","3608.86938476563","154.113998413086","3.18473856896162"
"3.93098685890436","3611.17407226563","154.813995361328","3.20037896744907"
"3.94873507320881","3613.337890625","155.514007568359","3.21597140282393"
"3.96660296246409","3615.57885742188","156.214004516602","3.23175452649593"
"3.98435117676854","3617.216796875","156.914001464844","3.24754859320819"
"4.00209939107299","3618.49340820313","157.613998413086","3.26319667510688"
"4.01990814134479","3620.64624023438","158.313995361328","3.27877490781248"
"4.03765635564923","3622.53735351563","159.014007568359","3.29436804167926"
"4.05546417459846","3624.74389648438","159.714004516602","3.31018213182688"
"4.07321285456419","3626.3876953125","160.414001464844","3.32588516175747"
"4.09102067351341","3628.62280273438","161.113998413086","3.34161636419594"
"4.10876935347915","3629.74584960938","161.813995361328","3.35731729865074"
"4.12657717242837","3631.85009765625","162.514007568359","3.37301916442811"
"4.1443258523941","3634.16845703125","163.214004516602","3.38888331316412"
"4.1621932759881","3635.98657226563","163.914001464844","3.40463826432824"
"4.17994149029255","3637.40234375","164.613998413086","3.42038343660533"
"4.19769017025828","3637.83325195313","165.313995361328","3.43608320690691"
"4.21549845486879","3640.5712890625","166.014007568359","3.45174665562809"
"4.23324666917324","3642.8349609375","166.714004516602","3.46755771897733"
"4.25105495378375","3644.12866210938","167.414001464844","3.48350685089827"
"4.2688031680882","3645.27197265625","168.113998413086","3.49931209348142"
"4.28655138239264","3646.357421875","168.813995361328","3.51507519371808"
"4.30435966700315","3648.82470703125","169.514007568359","3.53086669929326"
"4.32210834696889","3650.06518554688","170.214004516602","3.54663818143308"
"4.33997577056289","3652.18383789063","170.914001464844","3.56250628829002"
"4.35772398486733","3653.23461914063","171.613998413086","3.57847893610597"
"4.37547266483307","3655.017578125","172.313995361328","3.59438825398684"
"4.39322087913752","3655.48950195313","173.014007568359","3.61004378646612"
"4.41102916374803","3657.61254882813","173.714004516602","3.62592376768589"
"4.42883744835854","3659.49584960938","174.414001464844","3.64190153777599"
"4.44664526730776","3660.33520507813","175.113998413086","3.65777057595551"
"4.46439348161221","3660.98193359375","175.813995361328","3.67371737957001"
"4.48208255693316","3663.79296875","176.514007568359","3.68957128375769"
"4.49994998052716","3663.86743164063","177.214004516602","3.70540306903422"
"4.5176986604929","3666.16479492188","177.914001464844","3.72139341197908"
"4.53556654974818","3667.92041015625","178.613998413086","3.73753160238266"
"4.55331476405263","3668.22998046875","179.313995361328","3.75348911620677"
"4.57106297835708","3670.11108398438","180.014007568359","3.76947643235326"
"4.58881119266152","3671.2333984375","180.714004516602","3.78543511033058"
"4.60661947727203","3672.58178710938","181.414001464844","3.80132906138897"
"4.62442776188254","3674.33422851563","182.113998413086","3.81746655330062"
"4.64217597618699","3675.76245117188","182.813995361328","3.83364618755877"
"4.65992465615273","3675.771484375","183.514007568359","3.8495974149555"
"4.67767287045717","3677.1513671875","184.214004516602","3.86548251844943"
"4.69554029405117","3679.04272460938","184.914001464844","3.88146191835403"
"4.71334857866168","3680.16040039063","185.613998413086","3.89759731478989"
"4.73109725862741","3681.12329101563","186.313995361328","3.91367543488741"
"4.74890507757664","3681.66943359375","187.014007568359","3.92982643097639"
"4.7665941528976","3682.6875","187.714004516602","3.94589081406593"
"4.78440197184682","3684.0224609375","188.414001464844","3.96181410178542"
"4.80220979079604","3686.27172851563","189.113998413086","3.97792411968112"
"4.82001760974526","3686.83276367188","189.813995361328","3.99405974894762"
"4.83776675537229","3687.07373046875","190.514007568359","4.01024939492345"
"4.85551496967673","3688.119140625","191.214004516602","4.02635475620627"
"4.87332278862596","3689.58862304688","191.914001464844","4.04249085113406"
"4.89113107323647","3690.71337890625","192.613998413086","4.05862694606185"
"4.90893889218569","3691.89477539063","193.313995361328","4.07491158694029"
"4.92668710649014","3693.4765625","194.014007568359","4.09100670367479"
"4.94443625211716","3693.71240234375","194.714004516602","4.10723965615034"
"4.9621844664216","3694.50219726563","195.414001464844","4.12339717149735"
"4.9800518900156","3695.8115234375","196.113998413086","4.13958355784416"
"4.99780056998134","3696.92724609375","196.813995361328","4.15588077157736"
"5.01554878428578","3697.58056640625","197.514007568359","4.17204713448882"
"5.03335706889629","3698.04125976563","198.214004516602","4.18838951736689"
"5.05110528320074","3698.65991210938","198.914001464844","4.20463271439075"
"5.06891356781125","3700.0615234375","199.613998413086","4.22071386128664"
"5.08672138676047","3700.7490234375","200.313995361328","4.23699384555221"
"5.1045292057097","3702.38940429688","201.014007568359","4.25331061705947"
"5.12221828103065","3702.16357421875","201.714004516602","4.26957476884127"
"5.14002656564116","3703.3046875","202.414001464844","4.28579421713948"
"5.15783438459039","3703.70458984375","203.113998413086","4.30213566869497"
"5.17558306455612","3704.95288085938","203.813995361328","4.31833136826754"
"5.19339088350534","3705.93310546875","204.514007568359","4.33466397225857"
"5.21113909780979","3706.13110351563","205.214004516602","4.35093371197581"
"5.2289473824203","3706.39404296875","205.914001464844","4.36721788719296"
"5.24669606238604","3708.01684570313","206.613998413086","4.38346108421683"
"5.26450388133526","3709.11254882813","207.313995361328","4.3997778557241"
"5.28231170028448","3709.9833984375","208.014007568359","4.41612442955375"
"5.30006038025022","3710.34399414063","208.714004516602","4.43256460130215"
"5.31786819919944","3710.84619140625","209.414001464844","4.44898009300232"
"5.33561641350389","3710.4892578125","210.113998413086","4.46523493155837"
"5.35342516377568","3712.23193359375","210.813995361328","4.4814427383244"
"5.37117337808013","3713.78051757813","211.514007568359","4.49776230379939"
"5.38898119702935","3714.10668945313","212.214004516602","4.51426859945059"
"5.40672987699509","3714.65966796875","212.914001464844","4.53076558187604"
"5.42447809129953","3714.54907226563","213.613998413086","4.54710423946381"
"5.44228637591004","3714.8544921875","214.313995361328","4.5635225251317"
"5.46003505587578","3717.02124023438","215.014007568359","4.57993010058999"
"5.47790247946978","3716.86376953125","215.714004516602","4.59649879485369"
"5.49559108912945","3716.99194335938","216.414001464844","4.61298320442438"
"5.51339890807867","3717.59204101563","217.113998413086","4.62958216667175"
"5.53120719268918","3718.03100585938","217.813995361328","4.64600045233965"
"5.54895587265491","3718.615234375","218.514007568359","4.66237450018525"
"5.56676369160414","3719.51708984375","219.214004516602","4.67877695336938"
"5.58457197621465","3719.46997070313","219.914001464844","4.6954401768744"
"5.60232019051909","3719.45654296875","220.613998413086","4.71186358481646"
"5.62006840482354","3720.70336914063","221.313995361328","4.72841644659638"
"5.63787668943405","3720.84887695313","222.014007568359","4.74483193829656"
"5.65562536939979","3722.77709960938","222.714004516602","4.76135220378637"
"5.67349279299378","3722.1376953125","223.414001464844","4.77800844237208"
"5.69124147295952","3722.09716796875","224.113998413086","4.79450356215239"
"5.70898968726397","3722.80541992188","224.813995361328","4.811049439013"
"5.72679750621319","3723.50268554688","225.514007568359","4.82744257897139"
"5.74454618617892","3724.63110351563","226.214004516602","4.8440215177834"
"5.76235447078943","3724.5517578125","226.914001464844","4.86073037609458"
"5.78010268509388","3725.26000976563","227.613998413086","4.87730838358402"
"5.7979105040431","3725.3125","228.313995361328","4.89388033747673"
"5.81565918400884","3725.76391601563","229.014007568359","4.91045694798231"
"5.83346700295806","3726.48071289063","229.714004516602","4.92690270766616"
"5.85121568292379","3726.48901367188","230.414001464844","4.94366744533181"
"5.8690239675343","3728.1298828125","231.113998413086","4.96040005236864"
"5.88683178648353","3727.1904296875","231.813995361328","4.9771904014051"
"5.9045203961432","3727.24560546875","232.514007568359","4.99369483441114"
"5.92232868075371","3728.2724609375","233.214004516602","5.01036271452904"
"5.94013649970293","3728.32592773438","233.914001464844","5.02699473872781"
"5.95794478431344","3729.29833984375","234.613998413086","5.04377577453852"
"5.97569299861789","3728.9609375","235.313995361328","5.06053818389773"
"5.99344167858362","3728.75732421875","236.014007568359","5.07711805403233"
"6.01124949753284","3729.451171875","236.714004516602","5.09383343160152"
"6.02905731648207","3729.75463867188","237.414001464844","5.11041982099414"
"6.04686560109258","3730.53564453125","238.113998413086","5.12735499069095"
"6.06461428105831","3730.42553710938","238.813995361328","5.144027993083"
"6.08236249536276","3729.740234375","239.514007568359","5.1607103087008"
"6.10011117532849","3729.98950195313","240.214004516602","5.17726968973875"
"6.11791899427772","3730.287109375","240.914001464844","5.19401719793677"
"6.13572681322694","3731.61962890625","241.613998413086","5.21083502098918"
"6.15353509783745","3731.44287109375","242.313995361328","5.22754760459065"
"6.17128377780318","3731.18872070313","243.014007568359","5.24428347125649"
"6.18897238746285","3731.55883789063","243.714004516602","5.26105938479304"
"6.20683981105685","3732.36791992188","244.414001464844","5.27774868533015"
"6.22458849102259","3731.89184570313","245.113998413086","5.29454741626978"
"6.24245591461658","3732.75439453125","245.813995361328","5.31132705509663"
"6.26020412892103","3732.94580078125","246.514007568359","5.32812858000398"
"6.27789366990328","3731.421875","247.214004516602","5.34483511000872"
"6.2957014888525","3732.72045898438","247.914001464844","5.36166178062558"
"6.31350930780172","3732.47021484375","248.613998413086","5.37847774103284"
"6.33131759241223","3734.36767578125","249.313995361328","5.39540778845549"
"6.34906580671668","3733.81982421875","250.014007568359","5.41234808042645"
"6.36687409132719","3733.35791015625","250.714004516602","5.42917009443045"
"6.38456316664815","3733.46069335938","251.414001464844","5.44601958245039"
"6.40243059024215","3733.24047851563","252.113998413086","5.4629691876471"
"6.42023840919137","3733.98974609375","252.813995361328","5.47996396198869"
"6.43798662349582","3733.93994140625","253.514007568359","5.49689354375005"
"6.45579490810633","3734.18237304688","254.214004516602","5.51374210044742"
"6.47342437878251","3733.81982421875","254.914001464844","5.53048867732286"
"6.49129180237651","3733.73315429688","255.613998413086","5.54748717695475"
"6.50910008698702","3734.02197265625","256.313995361328","5.56448381394148"
"6.52684830129147","3734.29321289063","257.014007568359","5.58144506067038"
"6.54465612024069","3734.14501953125","257.713989257813","5.59837510809302"
"6.56240526586771","3733.15380859375","258.414001464844","5.61518827453256"
"6.58021308481693","3734.00415039063","259.114013671875","5.63211459666491"
"6.59796129912138","3734.56567382813","259.813995361328","5.64920157194138"
"6.61582918837667","3735.0556640625","260.514007568359","5.66627318039536"
"6.63351779803634","3734.32958984375","261.213989257813","5.68319112062454"
"6.65132561698556","3734.08032226563","261.914001464844","5.70006715133786"
"6.66907476261258","3733.82958984375","262.614013671875","5.71702001616359"
"6.6868825815618","3733.92504882813","263.313995361328","5.73411677032709"
"6.70469040051103","3734.7255859375","264.014007568359","5.75115298852324"
"6.72243861481547","3734.50439453125","264.713989257813","5.76816871762276"
"6.74024689942598","3734.79931640625","265.414001464844","5.78514812514186"
"6.75799511373043","3733.99096679688","266.114013671875","5.80214383080602"
"6.77580339834094","3733.84936523438","266.813995361328","5.81924291327596"
"6.79355207830668","3734.63061523438","267.514007568359","5.83625957369804"
"6.8113598972559","3734.74951171875","268.213989257813","5.85336331278086"
"6.82910811156034","3733.95947265625","268.914001464844","5.87036414071918"
"6.84691639617085","3733.51635742188","269.614013671875","5.88736962527037"
"6.8646646104753","3733.0380859375","270.313995361328","5.90441096574068"
"6.88247289508581","3733.6923828125","271.014007568359","5.9216832742095"
"6.90028117969632","3733.4775390625","271.713989257813","5.9388093650341"
"6.91796978935599","3733.10498046875","272.414001464844","5.95583394169807"
"6.93577760830522","3734.3720703125","273.114013671875","5.95737667754292"
"6.95358542725444","3734.23706054688","273.813995361328","5.95742138102651"
"6.97133457288146","3734.89013671875","274.514007568359","5.95748238265514"
"6.98914239183068","3734.50512695313","275.213989257813","5.95747632905841"
"7.00689060613513","3734.95068359375","275.914001464844","5.95742324367166"
"7.02469889074564","3734.64770507813","276.614013671875","5.95744606107473"
"7.04250670969486","3734.0625","277.313995361328","5.95748936757445"
"7.06025492399931","3734.32934570313","278.014007568359","5.95757504925132"
"7.07806367427111","3734.14575195313","278.713989257813","5.957524292171"
"7.09581188857555","3733.59448242188","279.414001464844","5.95746608451009"
"7.11361970752478","3733.58764648438","280.114013671875","5.95741346478462"
"7.13142799213529","3734.23974609375","280.813995361328","5.95738459378481"
"7.14917620643973","3733.64331054688","281.514007568359","5.95748517662287"
"7.16692442074418","3733.76635742188","282.213989257813","5.95756573602557"
"7.18479184433818","3733.75415039063","282.914001464844","5.95763185992837"
"7.2025409899652","3732.55029296875","283.614013671875","5.95765095204115"
"7.22034880891442","3732.0185546875","284.313995361328","5.95770450308919"
"7.23809702321887","3731.58837890625","285.014007568359","5.95761183649302"
"7.2558457031846","3732.09497070313","285.713989257813","5.95758436247706"
"7.27365352213383","3731.8681640625","286.414001464844","5.95756340771914"
"7.29146180674434","3731.95361328125","287.114013671875","5.95771661028266"
"7.30927009135485","3731.38037109375","287.813995361328","5.95762394368649"
"7.32695870101452","3730.83520507813","288.514007568359","5.95764210447669"
"7.34476651996374","3732.14135742188","289.213989257813","5.95758715644479"
"7.36251519992948","3731.23950195313","289.914001464844","5.95760671421885"
"7.3803230188787","3731.89428710938","290.614013671875","5.95762394368649"
"7.39813130348921","3730.490234375","291.313995361328","5.95765467733145"
"7.41587951779366","3731.16625976563","292.014007568359","5.95771800726652"
"7.43362819775939","3729.35205078125","292.713989257813","5.95765421167016"
"7.45137641206384","3729.61010742188","293.414001464844","5.95768447965384"
"7.46924383565784","3728.80200195313","294.114013671875","5.95774920657277"
"7.48699298128486","3729.25708007813","294.813995361328","5.95781160518527"
"7.50480080023408","3727.78173828125","295.514007568359","5.95774361863732"
"7.52254901453853","3727.37744140625","296.213989257813","5.95779623836279"
"7.54029769450426","3727.14916992188","296.914001464844","5.95784373581409"
"7.55810551345348","3726.88110351563","297.614013671875","5.95789076760411"
"7.57591333240271","3726.15283203125","298.313995361328","5.95782184973359"
"7.59372161701322","3726.32983398438","299.014007568359","5.95781579613686"
"7.61141069233418","3726.31982421875","299.713989257813","5.95793826505542"
"7.6292185112834","3725.14770507813","300.414001464844","5.95786422491074"
"7.64702633023262","3725.365234375","301.114013671875","5.95783069729805"
"7.66483461484313","3725.33764648438","301.813995361328","5.957858171314"
"7.68258282914758","3724.56640625","302.514007568359","5.95785025507212"
"7.70033150911331","3724.0673828125","303.213989257813","5.95788285136223"
"7.71813979372382","3723.06958007813","303.914001464844","5.95785630866885"
"7.73588800802827","3723.66772460938","304.614013671875","5.95784094184637"
"7.75369582697749","3724.2890625","305.313995361328","5.95788285136223"
"7.771504111588","3723.2001953125","306.014007568359","5.95796760171652"
"7.78925232589245","3722.20556640625","306.713989257813","5.95791591331363"
"7.80700100585818","3721.40869140625","307.414001464844","5.95799786970019"
"7.82474968582392","3720.04663085938","308.114013671875","5.95800811424851"
"7.84255750477314","3719.83935546875","308.813995361328","5.95791917294264"
"7.86036532372236","3720.40209960938","309.514007568359","5.95801416784525"
"7.87817314267159","3719.09692382813","310.213989257813","5.95809752121568"
"7.89586268365383","3719.35180664063","310.914001464844","5.95808448269963"
"7.91367050260305","3719.427734375","311.614013671875","5.9581445530057"
"7.93147832155228","3717.31909179688","312.313995361328","5.95809379592538"
"7.9492861405015","3717.92016601563","313.014007568359","5.95809426158667"
"7.96703435480595","3718.20825195313","313.713989257813","5.95808867365122"
"7.98478350043297","3717.67749023438","314.414001464844","5.95805468037724"
"8.00259131938219","3716.1357421875","315.114013671875","5.95807284116745"
"8.02039913833141","3715.56079101563","315.813995361328","5.95807284116745"
"8.03814828395844","3715.7939453125","316.514007568359","5.95805933699012"
"8.05589649826288","3714.44311523438","317.213989257813","5.9580709785223"
"8.0737043172121","3714.267578125","317.914001464844","5.95813477411866"
"8.09145253151655","3713.443359375","318.614013671875","5.95804629847407"
"8.10926035046577","3713.67578125","319.313995361328","5.958023481071"
"8.127068169415","3713.63208007813","320.014007568359","5.95806771889329"
"8.14481731504202","3713.18139648438","320.713989257813","5.9580453671515"
"8.16262513399124","3712.29028320313","321.414001464844","5.95815153792501"
"8.18037427961826","3710.8017578125","322.114013671875","5.95810636878014"
"8.19818209856749","3709.97729492188","322.813995361328","5.95812825486064"
"8.21593031287193","3710.02392578125","323.514007568359","5.9580965898931"
"8.23373813182116","3710.19165039063","324.213989257813","5.95801649615169"
"8.2514863461256","3708.90698242188","324.914001464844","5.95815386623144"
"8.2692950963974","3707.40576171875","325.614013671875","5.9581333771348"
"8.28710291534662","3706.4951171875","326.313995361328","5.95804862678051"
"8.30485112965107","3706.18017578125","327.014007568359","5.95814734697342"
"8.32265987992287","3705.46801757813","327.713989257813","5.95820276066661"
"8.34040716290474","3704.72924804688","328.414001464844","5.95824560150504"
"8.35821591317654","3703.69750976563","329.114013671875","5.95829216763377"
"8.37596412748098","3702.13134765625","329.813995361328","5.95824001356959"
"8.39377194643021","3701.6123046875","330.514007568359","5.95820927992463"
"8.41157976537943","3701.244140625","331.213989257813","5.95823070034385"
"8.42932891100645","3700.42749023438","331.914001464844","5.95826888456941"
"8.44713672995567","3699.62231445313","332.614013671875","5.95826841890812"
"8.4648858755827","3698.39526367188","333.313995361328","5.95820741727948"
"8.48269369453192","3697.15698242188","334.014007568359","5.95824653282762"
"8.50044190883636","3696.20434570313","334.713989257813","5.95820834860206"
"8.51819012314081","3695.9111328125","335.414001464844","5.95813104882836"
"8.53599794209003","3695.40087890625","336.114013671875","5.95817342400551"
"8.55380669236183","3693.39135742188","336.813995361328","5.95817063003778"
"8.57155490666628","3692.69360351563","337.514007568359","5.95817156136036"
"8.58930312097073","3692.21313476563","338.213989257813","5.95822185277939"
"8.60711093991995","3690.1376953125","338.914001464844","5.95823861658573"
"8.62486008554697","3689.1103515625","339.614013671875","5.95831731334329"
"8.64266790449619","3687.99755859375","340.313995361328","5.95835968852043"
"8.66047572344542","3685.65795898438","341.014007568359","5.95833081752062"
"8.67822486907244","3684.220703125","341.713989257813","5.95826702192426"
"8.69603268802166","3682.29467773438","342.414001464844","5.95818227156997"
"8.71377997100353","3681.27661132813","343.114013671875","5.95823442563415"
"8.73158872127533","3679.64038085938","343.813995361328","5.95823582261801"
"8.74939654022455","3677.44653320313","344.514007568359","5.95828471705318"
"8.767144754529","3675.697265625","345.213989257813","5.95824839547277"
"8.78489390015602","3672.87109375","345.914001464844","5.95830613747239"
"8.80270171910524","3670.6962890625","346.614013671875","5.95832243561745"
"8.82050953805447","3668.34741210938","347.313995361328","5.95835968852043"
"8.83831828832626","3666.41772460938","348.014007568359","5.95835503190756"
"8.85606557130814","3664.04858398438","348.713989257813","5.95838157460094"
"8.87381471693516","3659.94262695313","349.414001464844","5.95846306532621"
"8.89162253588438","3657.74682617188","350.114013671875","5.95844071358442"
"8.9093716815114","3652.78540039063","350.813995361328","5.95853151753545"
"8.92717950046062","3649.7138671875","351.514007568359","5.95845188945532"
"8.9449267834425","3646.35913085938","352.213989257813","5.9584267437458"
"8.96267592906952","3642.10180664063","352.914001464844","5.95849007368088"
"8.98048374801874","3638.13696289063","353.614013671875","5.95853803679347"
"8.99829156696796","3634.39599609375","354.313995361328","5.95850730314851"
"9.01610031723976","3629.31665039063","355.014007568359","5.95850544050336"
"9.03384853154421","3623.76831054688","355.713989257813","5.95851382240653"
"9.05165635049343","3619.28173828125","356.414001464844","5.95844304189086"
"9.06940549612045","3613.20434570313","357.114013671875","5.95845421776176"
"9.08721331506968","3607.81127929688","357.813995361328","5.95844862982631"
"9.1050211340189","3602.27734375","358.514007568359","5.95846632495523"
"9.12276934832335","3595.76049804688","359.213989257813","5.9584304690361"
"9.14057716727257","3589.43798828125","359.914001464844","5.95858180895448"
"9.15826577693224","3582.30932617188","360.614013671875","5.95858879387379"
"9.17613413184881","3574.96704101563","361.313995361328","5.95861347392201"
"9.19388327747583","3567.73266601563","362.014007568359","5.9586064890027"
"9.21169109642506","3560.56591796875","362.713989257813","5.95863908529282"
"9.22943837940693","3552.81567382813","363.414001464844","5.95857389271259"
"9.24724712967873","3544.0361328125","364.114013671875","5.95867540687323"
"9.26499534398317","3535.8125","364.813995361328","5.95863070338964"
"9.28286276757717","3528.17651367188","365.514007568359","5.95853151753545"
"9.30061191320419","3519.34741210938","366.213989257813","5.95861673355103"
"9.31836012750864","3509.47534179688","366.914001464844","5.95858693122864"
"9.33616794645786","3499.728515625","367.614013671875","5.95859531313181"
"9.35391616076231","3489.42993164063","368.313995361328","5.95864746719599"
"9.37172397971153","3480.18994140625","369.014007568359","5.95860974863172"
"9.38953179866076","3469.9384765625","369.713989257813","5.95871359109879"
"9.40728094428778","3459.37231445313","370.414001464844","5.95875876024365"
"9.425088763237","3447.84643554688","371.114013671875","5.95878064632416"
"9.44283790886402","3436.82934570313","371.813995361328","5.95868285745382"
"9.46064572781324","3424.68310546875","372.514007568359","5.95877505838871"
"9.47845354676247","3413.63256835938","373.213989257813","5.95870427787304"
"9.49620269238949","3401.76489257813","373.914001464844","5.95866469666362"
"9.51394997537136","3387.82666015625","374.614013671875","5.95872336998582"
"9.53175872564316","3376.14306640625","375.313995361328","5.9587643481791"
"9.54956654459238","3362.40356445313","376.014007568359","5.95865212380886"
"9.56731475889683","3350.77514648438","376.713989257813","5.9586763381958"
"9.58512350916862","3337.70654296875","377.414001464844","5.95866236835718"
"9.60287172347307","3323.23071289063","378.114013671875","5.95871964469552"
"9.62067954242229","3308.869140625","378.813995361328","5.95861673355103"
"9.63842775672674","3294.06640625","379.514007568359","5.95866236835718"
"9.65623557567596","3279.22705078125","380.213989257813","5.95860416069627"
"9.67404339462519","3264.11010742188","380.914001464844","5.95878297463059"
"9.69179254025221","3247.31958007813","381.614013671875","5.9588635340333"
"9.70960035920143","3230.76000976563","382.313995361328","5.95881883054972"
"9.72734950482845","3214.29711914063","383.014007568359","5.95885096117854"
"9.74515732377768","3198.24682617188","383.713989257813","5.95875922590494"
"9.76290553808212","3180.79345703125","384.414001464844","5.9588635340333"
"9.78071335703135","3163.23974609375","385.114013671875","5.95882860943675"
"9.79846157133579","3144.4560546875","385.813995361328","5.95871778205037"
"9.81627032160759","3125.69873046875","386.514007568359","5.95872336998582"
"9.83407814055681","3107.58544921875","387.213989257813","5.95878483727574"
"9.85182635486126","3088.17041015625","387.914001464844","5.95881883054972"
"9.86969377845526","3067.91625976563","388.614013671875","5.95882255584002"
"9.88738238811493","3048.46264648438","389.313995361328","5.95884397625923"
"9.90519020706415","3026.4580078125","390.014007568359","5.95877505838871"
"9.92299895733595","3005.71655273438","390.713989257813","5.95881231129169"
"9.9407471716404","2983.7119140625","391.414001464844","5.95881137996912"
"9.95855499058962","2960.64477539063","392.114013671875","5.9588230215013"
"9.97636280953884","2936.86303710938","392.813995361328","5.95890358090401"
"9.99411195516586","2913.083984375","393.514007568359","5.95890777185559"
"10.0119197741151","2888.82788085938","394.213989257813","5.95893617719412"
"10.0297275930643","2862.82983398438","394.914001464844","5.95898320898414"
"10.0474767386913","2837.1943359375","395.614013671875","5.95906423404813"
"10.0652845576406","2809.58081054688","396.313995361328","5.95907727256417"
"10.083032771945","2781.90893554688","397.014007568359","5.95896458253264"
"10.1008405908942","2753.95874023438","397.713989257813","5.9589883312583"
"10.1186484098434","2724.45458984375","398.414001464844","5.95901533961296"
"10.1363975554705","2692.01123046875","399.114013671875","5.95907354727387"
"10.1542053744197","2658.91040039063","399.813995361328","5.95898646861315"
"10.1720131933689","2620.20532226563","400.514007568359","5.95905631780624"
"10.1897623389959","2542.25073242188","401.213989257813","5.9588816948235"
"10.2076288312674","1867.416015625","401.914001464844","5.95901999622583"
"10.2256163954735","815.898803710938","402.614013671875","5.95905352383852"
"10.2434242144227","522.718200683594","403.313995361328","5.95901580527425"
"10.2555742487311","371.739776611328","403.7919921875","5.95902092754841"