File: Lab2/LabData/Tension/Test Run 2 10-6-2016 2 44 08 PM/DAQ- Crosshead, … - (Timed).csv
"File Path: F:\Test Run 2 10-6-2016 2 44 08 PM\DAQ- Crosshead, … - (Timed).csv
Test: MTS EM Tension (Extensometer) 28
Test Run: Test Run 2
Date: 10/6/2016 2:11:23 PM

"
"Crosshead ","Load ","Time ","Extensometer "
"mm","N","sec","mm"
"0.00250146126745676","38.6725387573242","0.115000002086163","0.000709167011336831"
"0.00744482485970366","93.4169235229492","0.314999997615814","0.00277074491350504"
"0.0125073065646575","151.23893737793","0.514999985694885","0.00487626402900787"
"0.017569787814864","207.103912353516","0.714999973773956","0.00695948392603896"
"0.0225727089855354","262.694976806641","0.915000021457672","0.00898877260624431"
"0.0276351911452366","318.779754638672","1.11500000953674","0.0111173476398108"
"0.032697669666959","374.095153808594","1.31500005722046","0.0130507587527973"
"0.0377601536456496","428.987823486328","1.51499998569489","0.0151048461702885"
"0.0428821913374122","482.8408203125","1.7150000333786","0.0170965595316375"
"0.0478851179650519","536.550964355469","1.91499996185303","0.0191494491446065"
"0.0530071556568146","590.796142578125","2.11500000953674","0.0211716487683589"
"0.0580696359975263","642.756164550781","2.31500005722046","0.0230484965868527"
"0.0631321163382381","694.547973632813","2.51500010490417","0.0250199173024157"
"0.0681945966789499","746.567993164063","2.71499991416931","0.026864903702517"
"0.0732570842956193","797.295776367188","2.91499996185303","0.0287375296466053"
"0.0783195573603734","847.827941894531","3.11500000953674","0.0306438087136485"
"0.0833820377010852","898.111755371094","3.31500005722046","0.0324800530506764"
"0.0884445253177546","947.389526367188","3.51500010490417","0.0342412167810835"
"0.0935665593715385","996.991516113281","3.71499991416931","0.0361064448952675"
"0.0986290397122502","1045.89135742188","3.91499996185303","0.0380202982341871"
"0.10369152732892","1094.12438964844","4.11499977111816","0.0397718613385223"
"0.108813561382703","1142.43432617188","4.31500005722046","0.0415020440414082"
"0.113816488010343","1189.55932617188","4.5149998664856","0.0431934531661682"
"0.118938529340085","1236.60180664063","4.71500015258789","0.0449491744802799"
"0.124001002404839","1283.26635742188","4.91499996185303","0.0467425197712146"
"0.129003921756521","1328.85961914063","5.11499977111816","0.0483647963847034"
"0.134125963086262","1374.60595703125","5.31500005722046","0.0500472560815979"
"0.139188457978889","1420.51672363281","5.5149998664856","0.0518333981744945"
"0.144250923767686","1464.66540527344","5.71500015258789","0.0534173232153989"
"0.149372965097427","1509.31127929688","5.91499996185303","0.0551220582565293"
"0.154435459990054","1553.2099609375","6.11499977111816","0.0566223825444467"
"0.159497925778851","1596.23754882813","6.31500005722046","0.0583073669986334"
"0.164560406119563","1639.35461425781","6.5149998664856","0.059948317357339"
"0.16956334002316","1680.87976074219","6.71500015258789","0.061548562371172"
"0.174685366800986","1722.35461425781","6.91499996185303","0.0630982976872474"
"0.179747861693613","1763.88049316406","7.11499977111816","0.0646590779069811"
"0.184869903023355","1804.95776367188","7.31500005722046","0.0662287275190465"
"0.189932383364066","1846.17919921875","7.5149998664856","0.0678149663144723"
"0.194994863704778","1885.57751464844","7.71500015258789","0.0693641341058537"
"0.20005734404549","1925.34875488281","7.91499996185303","0.0709424275555648"
"0.205179385375232","1964.74462890625","8.11499977111816","0.0723644698155113"
"0.210182304726914","2003.64819335938","8.3149995803833","0.0739023598725908"
"0.215244785067625","2042.63745117188","8.51500034332275","0.0755755172576755"
"0.220366826397367","2079.36840820313","8.71500015258789","0.0770266415202059"
"0.225429306738079","2116.4931640625","8.91499996185303","0.0784716685302556"
"0.23055134806782","2154.28100585938","9.11499977111816","0.079987759818323"
"0.235554267419502","2190.287109375","9.3149995803833","0.0814590166555718"
"0.240676308749244","2223.93017578125","9.51500034332275","0.0829334385343827"
"0.245738803641871","2260.01147460938","9.71500015258789","0.0844306850922294"
"0.250801269430667","2293.5400390625","9.91499996185303","0.0858340936247259"
"0.255863764323294","2327.65869140625","10.1149997711182","0.0874356119311415"
"0.260926230112091","2360.19140625","10.3149995803833","0.0888491704245098"
"0.265988695900887","2392.26611328125","10.5150003433228","0.0902856336324476"
"0.271110737230629","2423.83056640625","10.7150001525879","0.0918940058909357"
"0.276173232123256","2454.35961914063","10.914999961853","0.0933388655539602"
"0.281235727015883","2485.20776367188","11.1149997711182","0.0949035238591023"
"0.286298192804679","2515.36767578125","11.3149995803833","0.0963197235250846"
"0.291360687697306","2544.50073242188","11.5150003433228","0.0977712625171989"
"0.296482699923217","2573.42431640625","11.7150001525879","0.0993681023828685"
"0.301545194815844","2599.96655273438","11.914999961853","0.100870784081053"
"0.306607660604641","2627.04296875","12.1149997711182","0.102459860499948"
"0.311729731038213","2653.90551757813","12.3149995803833","0.104105951322708"
"0.316792196827009","2679.20727539063","12.5150003433228","0.105733808595687"
"0.321854691719636","2704.78564453125","12.7150001525879","0.107299078081269"
"0.326917157508433","2728.9951171875","12.914999961853","0.108980457298458"
"0.331979623297229","2751.53564453125","13.1149997711182","0.110585642687511"
"0.337101664626971","2774.64892578125","13.3149995803833","0.112290901597589"
"0.342164159519598","2796.82983398438","13.5150003433228","0.114069494884461"
"0.347226654412225","2817.70556640625","13.7150001525879","0.115839939098805"
"0.352289120201021","2837.90893554688","13.914999961853","0.117664101708215"
"0.357351615093648","2857.12841796875","14.1149997711182","0.119512442324776"
"0.362473627319559","2876.26708984375","14.3149995803833","0.121531120385043"
"0.367536122212186","2894.798828125","14.5150003433228","0.123472505947575"
"0.372539041563869","2910.92456054688","14.7150001525879","0.125536724226549"
"0.37766108289361","2929.50537109375","14.914999961853","0.127647566841915"
"0.382783124223351","2945.76904296875","15.1149997711182","0.12986923684366"
"0.387845619115978","2961.43408203125","15.3149995803833","0.132161789224483"
"0.39296763134189","2976.63452148438","15.5150003433228","0.134551068185829"
"0.398030126234517","2991.22265625","15.7150001525879","0.136981558171101"
"0.403092621127144","3005.13061523438","15.914999961853","0.139526382554322"
"0.40815508691594","3017.84423828125","16.1149997711182","0.142187651363201"
"0.413217581808567","3028.74462890625","16.3150005340576","0.144858029671013"
"0.418280076701194","3040.62817382813","16.5149993896484","0.147815720993094"
"0.42334251338616","3050.65063476563","16.7150001525879","0.150878229760565"
"0.428464554715902","3058.38012695313","16.9150009155273","0.154019973706454"
"0.433586625149474","3067.357421875","17.1149997711182","0.157281101564877"
"0.438589544501156","3073.64794921875","17.3150005340576","0.160724404850043"
"0.443711585830897","3079.93334960938","17.5149993896484","0.16435697034467"
"0.448774080723524","3085.70874023438","17.7150001525879","0.167946214787662"
"0.45383651740849","3090.513671875","17.9150009155273","0.171672392752953"
"0.458899012301117","3095.33129882813","18.1149997711182","0.175467226654291"
"0.463961507193744","3098.91235351563","18.3150005340576","0.179479218786582"
"0.469083548523486","3102.2265625","18.5149993896484","0.183414900675416"
"0.474205589853227","3105.49951171875","18.7150001525879","0.187550191185437"
"0.479268084745854","3108.52954101563","18.9150009155273","0.1916865730891"
"0.48433052143082","3110.97924804688","19.1149997711182","0.195957327377982"
"0.489452562760562","3114.08544921875","19.3150005340576","0.20020769443363"
"0.494455511216074","3116.3056640625","19.5149993896484","0.204529715119861"
"0.499577552545816","3118.09155273438","19.7150001525879","0.208837853278965"
"0.504640047438443","3119.97827148438","19.9150009155273","0.213270628591999"
"0.509702484123409","3122.99462890625","20.1149997711182","0.2176550187869"
"0.514824583660811","3124.3154296875","20.3150005340576","0.222159258555621"
"0.519887020345777","3126.08251953125","20.5149993896484","0.226596675929613"
"0.52500911988318","3128.10473632813","20.7150001525879","0.231124780839309"
"0.530012010131031","3129.66357421875","20.9150009155273","0.235580475418828"
"0.535074446815997","3130.52124023438","21.1149997711182","0.240162160480395"
"0.540256092790514","3132.6513671875","21.3150005340576","0.244702911004424"
"0.545258983038366","3133.8564453125","21.5149993896484","0.249090429861099"
"0.550321477930993","3135.05859375","21.7150001525879","0.253618723945692"
"0.555443519260734","3137.42431640625","21.9150009155273","0.258174375630915"
"0.560506014153361","3138.3583984375","22.1149997711182","0.262788409600034"
"0.565628055483103","3139.61083984375","22.3150005340576","0.267489755060524"
"0.570690492168069","3142.08422851563","22.5149993896484","0.272088684141636"
"0.575752987060696","3142.09692382813","22.7150001525879","0.276602426311001"
"0.580875028390437","3143.33544921875","22.9150009155273","0.281210901448503"
"0.585937523283064","3144.61596679688","23.1149997711182","0.285899790469557"
"0.591000018175691","3145.54516601563","23.3150005340576","0.290485273580998"
"0.596122001297772","3147.15478515625","23.5149993896484","0.295117817586288"
"0.60118455439806","3148.11157226563","23.7150001525879","0.299788196571171"
"0.606246991083026","3149.12475585938","23.9150009155273","0.304420274915174"
"0.611309485975653","3150.369140625","24.1149997711182","0.309056747937575"
"0.61637198086828","3151.732421875","24.3150005340576","0.313668831950054"
"0.621434475760907","3152.6044921875","24.5149993896484","0.318328471621498"
"0.626556458882988","3154.50415039063","24.7150001525879","0.322922831401229"
"0.631618953775615","3155.27099609375","24.9150009155273","0.327694549923763"
"0.636740995105356","3156.525390625","25.1149997711182","0.332253490341827"
"0.641803489997983","3156.81616210938","25.3150005340576","0.336938217515126"
"0.64686598489061","3158.171875","25.5149993896484","0.341515784384683"
"0.651988026220351","3159.17993164063","25.7150001525879","0.346215587342158"
"0.656990916468203","3160.03271484375","25.9150009155273","0.35089478478767"
"0.66205341136083","3162.1162109375","26.1149997711182","0.355572788976133"
"0.667175452690572","3163.431640625","26.3150005340576","0.360234931576997"
"0.672237947583199","3163.01416015625","26.5149993896484","0.364992913091555"
"0.677419535350055","3165.56909179688","26.7150001525879","0.369641988072544"
"0.682422483805567","3166.44213867188","26.9150009155273","0.374397408450022"
"0.687544466927648","3167.08056640625","27.1149997711182","0.379081291612238"
"0.692606961820275","3167.90869140625","27.3150005340576","0.383768288884312"
"0.697669456712902","3169.80639648438","27.5149993896484","0.388439482776448"
"0.702731893397868","3170.44921875","27.7150001525879","0.393185153370723"
"0.707794446498156","3171.35888671875","27.9150009155273","0.397832016460598"
"0.712856883183122","3172.16455078125","28.1149997711182","0.402547360863537"
"0.717978982720524","3173.01293945313","28.3150005340576","0.407265295507386"
"0.72304141940549","3174.80029296875","28.5149993896484","0.411945919040591"
"0.728163460735232","3175.29541015625","28.7150001525879","0.416646216763183"
"0.733225955627859","3176.28735351563","28.9150009155273","0.42134165414609"
"0.738288392312825","3177.65625","29.1149997711182","0.425979145802557"
"0.743410491850227","3178.51318359375","29.3150005340576","0.430577027145773"
"0.748472928535193","3179.50122070313","29.5149993896484","0.435394904343411"
"0.753475818783045","3181.2529296875","29.7150001525879","0.439884694060311"
"0.758597918320447","3182.26513671875","29.9150009155273","0.444639998022467"
"0.763719901442528","3183.33056640625","30.1149997711182","0.449353421572596"
"0.768782454542816","3184.49536132813","30.3150005340576","0.453975197160617"
"0.773844891227782","3185.30224609375","30.5149993896484","0.458782014902681"
"0.778907386120409","3186.37841796875","30.7150001525879","0.463391072116792"
"0.78402942745015","3187.28149414063","30.9150009155273","0.468078622361645"
"0.789091864135116","3189.09545898438","31.1149997711182","0.472800806164742"
"0.794154417235404","3188.63159179688","31.3150005340576","0.477509456686676"
"0.799276400357485","3190.16796875","31.5149993896484","0.482214789371938"
"0.804338953457773","3191.251953125","31.7150001525879","0.486863864352927"
"0.809460936579853","3192.2373046875","31.9150009155273","0.49161387141794"
"0.814523373264819","3193.65307617188","32.1150016784668","0.496267050039023"
"0.819526379927993","3194.29150390625","32.314998626709","0.500914116855711"
"0.824648363050073","3194.9970703125","32.5149993896484","0.505563628394157"
"0.829770462587476","3195.89672851563","32.7150001525879","0.51020976388827"
"0.834832899272442","3196.9736328125","32.9150009155273","0.514865794684738"
"0.839895394165069","3198.98828125","33.1150016784668","0.519479624927044"
"0.84501743549481","3199.40991210938","33.314998626709","0.524100032635033"
"0.850079872179776","3201.04077148438","33.5149993896484","0.528777309227735"
"0.855142425280064","3200.58056640625","33.7150001525879","0.533448066562414"
"0.860145315527916","3202.1435546875","33.9150009155273","0.538106192834675"
"0.865267356857657","3204.0224609375","34.1150016784668","0.54272823035717"
"0.870389398187399","3205.2197265625","34.314998626709","0.547419534996152"
"0.875451834872365","3205.62060546875","34.5149993896484","0.552133598830551"
"0.880573934409767","3207.10620117188","34.7150001525879","0.556746439542621"
"0.885636371094733","3207.86865234375","34.9150009155273","0.561380875296891"
"0.890758470632136","3208.24755859375","35.1150016784668","0.566113565582782"
"0.895820907317102","3209.98413085938","35.314998626709","0.570765638258308"
"0.900823855772614","3210.52172851563","35.5149993896484","0.57533715153113"
"0.905886292457581","3211.68603515625","35.7150001525879","0.580064486712217"
"0.911008333787322","3213.1484375","35.9150009155273","0.584687630180269"
"0.916070828679949","3213.62475585938","36.1150016784668","0.589315197430551"
"0.921192870009691","3214.29052734375","36.314998626709","0.593926815781742"
"0.926255364902318","3214.861328125","36.5149993896484","0.598522659856826"
"0.931377406232059","3215.8994140625","36.7150001525879","0.603196036536247"
"0.936439842917025","3218.228515625","36.9150009155273","0.60774851590395"
"0.941502396017313","3218.45703125","37.1150016784668","0.612338248174638"
"0.946564832702279","3219.294921875","37.314998626709","0.617003533989191"
"0.951627327594906","3220.77905273438","37.5149993896484","0.621544313617051"
"0.956749368924648","3222.16381835938","37.7150001525879","0.62618387164548"
"0.961871410254389","3222.73388671875","37.9150009155273","0.63086545560509"
"0.966933905147016","3223.24609375","38.1150016784668","0.635520555078983"
"0.971996341831982","3224.31396484375","38.314998626709","0.640141544863582"
"0.977118383161724","3226.16015625","38.5149993896484","0.644723535515368"
"0.982180936262012","3226.71997070313","38.7150001525879","0.649430323392153"
"0.987243372946978","3227.8056640625","38.9150009155273","0.654041185043752"
"0.992305926047266","3228.86499023438","39.1150016784668","0.658585981000215"
"0.997368362732232","3229.10131835938","39.314998626709","0.663280603475869"
"1.00249040406197","3230.5947265625","39.5149993896484","0.66788581898436"
"1.00755284074694","3231.18896484375","39.7150001525879","0.67243684316054"
"1.01267488207668","3232.0400390625","39.9150009155273","0.677084201015532"
"1.01767783053219","3233.43041992188","40.1150016784668","0.681639474350959"
"1.02274026721716","3233.84252929688","40.314998626709","0.6862414884381"
"1.0278623085469","3235.6015625","40.5149993896484","0.690767425112426"
"1.03298434987664","3237.0751953125","40.7150001525879","0.69535564398393"
"1.03798729833215","3236.56982421875","40.9150009155273","0.699844444170594"
"1.0431093396619","3238.50439453125","41.1150016784668","0.704510719515383"
"1.04817189276218","3239.04541015625","41.314998626709","0.709061278030276"
"1.0532938176766","3240.02612304688","41.5149993896484","0.713690416887403"
"1.05835625436157","3241.28344726563","41.7150001525879","0.718361348845065"
"1.06341880746186","3241.56274414063","41.9150009155273","0.722803582902998"
"1.0685408487916","3242.72094726563","42.1150016784668","0.727514503523707"
"1.07360340189189","3243.74389648438","42.314998626709","0.732056330889463"
"1.07866583857685","3244.74365234375","42.5149993896484","0.736682093702257"
"1.08372827526182","3245.55859375","42.7150001525879","0.741284864488989"
"1.08879082836211","3246.65063476563","42.9150009155273","0.745808938518167"
"1.09391286969185","3247.54028320313","43.1150016784668","0.750448554754257"
"1.09897530637681","3248.61450195313","43.314998626709","0.755001441575587"
"1.10397825483233","3249.17919921875","43.5149993896484","0.759515154641122"
"1.10910017974675","3250.26806640625","43.7150001525879","0.764110183808953"
"1.11422233749181","3250.81591796875","43.9150009155273","0.768667319789529"
"1.11928477417678","3251.50268554688","44.1150016784668","0.773288076743484"
"1.12440681550652","3252.91333007813","44.314998626709","0.777830719016492"
"1.12946925219148","3253.4677734375","44.5149993896484","0.782409100793302"
"1.13453168887645","3254.60888671875","44.7150001525879","0.787009601481259"
"1.13965384662151","3255.31298828125","44.9150009155273","0.791532977018505"
"1.14465679507703","3256.54541015625","45.1150016784668","0.796177075244486"
"1.14977883640677","3257.1826171875","45.314998626709","0.800671346951276"
"1.15484127309173","3258.49072265625","45.5149993896484","0.805318646598607"
"1.15996331442147","3258.91040039063","45.7150001525879","0.80991763388738"
"1.16508535575122","3260.25708007813","45.9150009155273","0.814440601971"
"1.17008830420673","3260.60693359375","46.1150016784668","0.819022243376821"
"1.17521034553647","3261.93994140625","46.314998626709","0.823600625153631"
"1.18027278222144","3262.44970703125","46.5149993896484","0.828168238513172"
"1.18533533532172","3263.48120117188","46.7150001525879","0.832801044452935"
"1.19039777200669","3264.82666015625","46.9150009155273","0.837271567434072"
"1.19546020869166","3264.72900390625","47.1150016784668","0.841873697936535"
"1.20052264537662","3265.37524414063","47.314998626709","0.846392125822604"
"1.20570429135114","3266.99462890625","47.5149993896484","0.850927550345659"
"1.21076684445143","3267.744140625","47.7150001525879","0.855539925396442"
"1.21582928113639","3268.74365234375","47.9150009155273","0.860030122566968"
"1.22089171782136","3270.05297851563","48.1150016784668","0.864540517795831"
"1.22595427092165","3269.41552734375","48.314998626709","0.869053590577096"
"1.23107619583607","3270.71606445313","48.5149993896484","0.873647222761065"
"1.23613886535168","3272.18432617188","48.7150001525879","0.878252787515521"
"1.24120130203664","3272.50659179688","48.9150009155273","0.882733380421996"
"1.24632322695106","3274.23291015625","49.1150016784668","0.887329166289419"
"1.25138578005135","3274.49047851563","49.314998626709","0.89183688396588"
"1.25650770496577","3275.04614257813","49.5149993896484","0.896485464181751"
"1.26157037448138","3276.59643554688","49.7150001525879","0.901055347640067"
"1.26657320652157","3276.865234375","49.9150009155273","0.905672670342028"
"1.27175485249609","3277.99047851563","50.1150016784668","0.910271133761853"
"1.27681728918105","3278.48754882813","50.314998626709","0.914724718313664"
"1.28182012122124","3279.40112304688","50.5149993896484","0.919396232347935"
"1.28694227896631","3279.61352539063","50.7150001525879","0.923931656870991"
"1.29200471565127","3281.49658203125","50.9150009155273","0.928526045754552"
"1.29712675698102","3281.64404296875","51.1150016784668","0.933025265112519"
"1.30218919366598","3282.18286132813","51.314998626709","0.937534554395825"
"1.30719225853682","3282.72338867188","51.5149993896484","0.942050246521831"
"1.31231429986656","3283.69604492188","51.7150001525879","0.946572632528842"
"1.31743622478098","3285.26904296875","51.9150009155273","0.951116380747408"
"1.32249866146594","3285.78369140625","52.1150016784668","0.9557064040564"
"1.32756121456623","3287.03466796875","52.314998626709","0.960259232670069"
"1.33262376766652","3287.6025390625","52.5149993896484","0.964825449045748"
"1.33774580899626","3288.7451171875","52.7150001525879","0.969428103417158"
"1.34280824568123","3289.38818359375","52.9150009155273","0.973924645222723"
"1.34787068236619","3289.3427734375","53.1150016784668","0.978555646724999"
"1.35299272369593","3290.86962890625","53.314998626709","0.98312774207443"
"1.35805527679622","3291.1083984375","53.5149993896484","0.987662933766842"
"1.36317731812596","3292.30590820313","53.7150001525879","0.992273562587798"
"1.36823975481093","3293.11206054688","53.9150009155273","0.996841234154999"
"1.3733021914959","3293.60327148438","54.1150016784668","1.00129877682775"
"1.37842423282564","3294.5126953125","54.314998626709","1.00593850947917"
"1.38348678592592","3295.279296875","54.5149993896484","1.01042131427675"
"1.38848973438144","3295.49682617188","54.7150001525879","1.01496826391667"
"1.39361165929586","3296.64013671875","54.9150009155273","1.01945328060538"
"1.39867409598082","3297.96899414063","55.1150016784668","1.0240221163258"
"1.40379625372589","3298.44360351563","55.314998626709","1.02844333741814"
"1.40891829505563","3299.36962890625","55.5149993896484","1.03311089333147"
"1.41392124351114","3299.689453125","55.7150001525879","1.03768217377365"
"1.41904316842556","3300.73583984375","55.9150009155273","1.04224518872797"
"1.42410572152585","3301.47534179688","56.1150016784668","1.04671914596111"
"1.42916827462614","3301.9169921875","56.314998626709","1.05129519943148"
"1.43429019954056","3302.62353515625","56.5149993896484","1.05589895974845"
"1.43929314799607","3303.3193359375","56.7150001525879","1.06039911042899"
"1.44441518932581","3303.29516601563","56.9150009155273","1.065066549927"
"1.44953723065555","3304.81005859375","57.1150016784668","1.06952572241426"
"1.45459978375584","3305.10888671875","57.314998626709","1.07406487222761"
"1.45966222044081","3306.087890625","57.5149993896484","1.07866257894784"
"1.46478426177055","3307.13598632813","57.7150001525879","1.08323292806745"
"1.46984669845551","3306.88696289063","57.9150009155273","1.08766544144601"
"1.47490913514048","3307.7001953125","58.1150016784668","1.0923205409199"
"1.47997168824077","3309.33520507813","58.314998626709","1.09678215812892"
"1.48503412492573","3309.42895507813","58.5149993896484","1.10143434721977"
"1.49015616625547","3310.73315429688","58.7150001525879","1.1059952666983"
"1.49521860294044","3310.66015625","58.9150009155273","1.11039960756898"
"1.50028127245605","3311.29248046875","59.1150016784668","1.1150575010106"
"1.50540319737047","3312.09521484375","59.314998626709","1.1196038685739"
"1.51040614582598","3312.12524414063","59.5149993896484","1.12416688352823"
"1.51552818715572","3314.00830078125","59.7150001525879","1.12875911872834"
"1.52059062384069","3313.90307617188","59.9150009155273","1.13333796616644"
"1.52565317694098","3314.17895507813","60.1150016784668","1.13780843093991"
"1.53077521827072","3315.51953125","60.314998626709","1.14243966527283"
"1.53583765495569","3316.14868164063","60.5149993896484","1.1470066383481"
"1.54095969628543","3317.26440429688","60.7150001525879","1.15158339031041"
"1.54602213297039","3317.9462890625","60.9150009155273","1.15626538172364"
"1.55102508142591","3318.25561523438","61.1150016784668","1.16077566053718"
"1.55614712275565","3319.2216796875","61.314998626709","1.16532947868109"
"1.56126916408539","3319.63061523438","61.5149993896484","1.16985128261149"
"1.56633160077035","3320.00244140625","61.7150001525879","1.17447949014604"
"1.5714536421001","3321.2861328125","61.9150009155273","1.17910478729755"
"1.57651619520038","3322.25268554688","62.1150016784668","1.18372752331197"
"1.58157863188535","3321.9404296875","62.314998626709","1.18825712706894"
"1.58664106857032","3322.76538085938","62.5149993896484","1.19280454237014"
"1.59164401702583","3322.57373046875","62.7150001525879","1.1972674401477"
"1.59676605835557","3323.650390625","62.9150009155273","1.20177248027176"
"1.60188821610063","3324.708984375","63.1150016784668","1.20637693908066"
"1.6069506527856","3325.96337890625","63.314998626709","1.21093518100679"
"1.61207269411534","3326.49072265625","63.5149993896484","1.21550459880382"
"1.61713513080031","3326.65893554688","63.7150001525879","1.22010160703212"
"1.62225728854537","3326.86254882813","63.9150009155273","1.22469605412334"
"1.62731972523034","3326.94775390625","64.1149978637695","1.22935371473432"
"1.6323821619153","3327.73681640625","64.3150024414063","1.23385002370924"
"1.63744459860027","3328.40966796875","64.5149993896484","1.23848940711468"
"1.64250703528523","3329.28295898438","64.7149963378906","1.24302844051272"
"1.6476291930303","3329.57104492188","64.9150009155273","1.24759331811219"
"1.65275123436004","3330.72827148438","65.1149978637695","1.25222187489271"
"1.65775406640023","3331.16430664063","65.3150024414063","1.25686230603606"
"1.66287610772997","3331.16845703125","65.5149993896484","1.26140494830906"
"1.66793854441494","3332.30883789063","65.7149963378906","1.26588437706232"
"1.67300109751523","3332.55200195313","65.9150009155273","1.27042457461357"
"1.67812313884497","3333.12524414063","66.1149978637695","1.27502193208784"
"1.68312608730048","3333.859375","66.3150024414063","1.27951358444989"
"1.68824812863022","3334.18579101563","66.5149993896484","1.2841421412304"
"1.69337005354464","3335.88012695313","66.7149963378906","1.2888191267848"
"1.69843260664493","3336.46752929688","66.9150009155273","1.29335466772318"
"1.70349515974522","3336.70556640625","67.1149978637695","1.29800813738257"
"1.70861708465964","3336.91796875","67.3150024414063","1.30256405100226"
"1.71367963775992","3336.7314453125","67.5149993896484","1.307153259404"
"1.71880156267434","3337.734375","67.7149963378906","1.31175224669278"
"1.72380462754518","3338.00952148438","67.9150009155273","1.31638045422733"
"1.72886706423014","3337.96655273438","68.1149978637695","1.32090994156897"
"1.73398910555989","3339.97680664063","68.3150024414063","1.32553360890597"
"1.73911114688963","3340.5732421875","68.5149993896484","1.33017671760172"
"1.74417369998991","3339.95043945313","68.7149963378906","1.33479328360409"
"1.74923613667488","3341.0048828125","68.9150009155273","1.33937632199377"
"1.75429857335985","3341.869140625","69.1149978637695","1.34399812668562"
"1.75942061468959","3341.49829101563","69.3150024414063","1.34857895318419"
"1.76448305137455","3342.60546875","69.5149993896484","1.35324732400477"
"1.76954560447484","3343.09936523438","69.7149963378906","1.35773536749184"
"1.77466764580458","3343.56713867188","69.9150009155273","1.36226101312786"
"1.77973008248955","3344.0947265625","70.1149978637695","1.36685639154166"
"1.78479251917452","3344.66577148438","70.3150024414063","1.37148785870522"
"1.7898550722748","3344.96142578125","70.5149993896484","1.37596530839801"
"1.79491762537509","3344.55346679688","70.7149963378906","1.38051575049758"
"1.80003966670483","3346.3154296875","70.9150009155273","1.38512335252017"
"1.8051021033898","3346.25024414063","71.1149978637695","1.38973398134112"
"1.81022414471954","3346.6025390625","71.3150024414063","1.39435601886362"
"1.81528658140451","3347.23217773438","71.5149993896484","1.39895768370479"
"1.8203491345048","3347.5966796875","71.7149963378906","1.40359590295702"
"1.82547117583454","3348.09643554688","71.9150009155273","1.40817533247173"
"1.8305336125195","3348.61450195313","72.1149978637695","1.41285022255033"
"1.83553644455969","3348.95532226563","72.3150024414063","1.41733628697693"
"1.84065860230476","3349.49438476563","72.5149993896484","1.42184924334288"
"1.8457806436345","3349.94995117188","72.7149963378906","1.42657954711467"
"1.85084308031946","3349.982421875","72.9150009155273","1.43113941885531"
"1.85596512164921","3350.61889648438","73.1149978637695","1.43577728886157"
"1.8609679536894","3351.17700195313","73.3150024414063","1.44042074680328"
"1.86609011143446","3351.5498046875","73.5149993896484","1.44490401726216"
"1.87115254811943","3351.36474609375","73.7149963378906","1.44959520548582"
"1.87621510121971","3351.87426757813","73.9150009155273","1.45410920958966"
"1.88127753790468","3352.79052734375","74.1149978637695","1.45861320197582"
"1.88633997458965","3353.32568359375","74.3150024414063","1.46325526293367"
"1.89146213233471","3353.96557617188","74.5149993896484","1.46778638008982"
"1.89658405724913","3354.45190429688","74.7149963378906","1.47259456571192"
"1.90164661034942","3354.27783203125","74.9150009155273","1.47716875653714"
"1.90676853526384","3355.56762695313","75.1149978637695","1.48173898924142"
"1.91183108836412","3355.93701171875","75.3150024414063","1.48644123692065"
"1.91689364146441","3355.33325195313","75.5149993896484","1.49105780292302"
"1.92195607814938","3356.10717773438","75.7149963378906","1.49564107414335"
"1.92701851483434","3356.29760742188","75.9150009155273","1.50025764014572"
"1.93208095151931","3356.81762695313","76.1149978637695","1.50492519605905"
"1.93720299284905","3357.05712890625","76.3150024414063","1.5095507260412"
"1.94226554594934","3357.42456054688","76.5149993896484","1.51415134314448"
"1.94738758727908","3358.01733398438","76.7149963378906","1.51882623322308"
"1.95245002396405","3358.60278320313","76.9150009155273","1.52340962085873"
"1.95751246064901","3358.52490234375","77.1149978637695","1.52801908552647"
"1.96257513016462","3358.94677734375","77.3150024414063","1.53269374277443"
"1.96763756684959","3359.01123046875","77.5149993896484","1.53729063458741"
"1.97270000353456","3360.24389648438","77.7149963378906","1.5418988186866"
"1.9778220448643","3359.87915039063","77.9150009155273","1.54648360330611"
"1.98288448154926","3360.2568359375","78.1149978637695","1.55115488450974"
"1.988006522879","3360.40356445313","78.3150024414063","1.55578821431845"
"1.99306895956397","3361.111328125","78.5149993896484","1.56039046123624"
"1.99813162907958","3361.35034179688","78.7149963378906","1.56504625920206"
"2.00325343757868","3362.14135742188","78.9150009155273","1.5697511844337"
"2.00831610709429","3361.50659179688","79.1149978637695","1.57427648082376"
"2.01337854377925","3362.57202148438","79.3150024414063","1.57892017159611"
"2.018500585109","3363.64721679688","79.5149993896484","1.58365583047271"
"2.02356302179396","3363.3037109375","79.7149963378906","1.5882762381807"
"2.02862545847893","3363.494140625","79.9150009155273","1.5929244691506"
"2.03368812799454","3363.48193359375","80.1149978637695","1.59756804350764"
"2.03875033184886","3364.58520507813","80.3150024414063","1.60219217650592"
"2.04387260600924","3364.36279296875","80.5149993896484","1.60687125753611"
"2.04893504269421","3365.18627929688","80.7149963378906","1.6114586032927"
"2.05405708402395","3364.6669921875","80.9150009155273","1.61609542556107"
"2.05911952070892","3365.50415039063","81.1149978637695","1.62074423860759"
"2.06418195739388","3365.37133789063","81.3150024414063","1.62531377281994"
"2.06930399872363","3365.81689453125","81.5149993896484","1.6299644485116"
"2.07436666823924","3365.87646484375","81.7149963378906","1.63454364519566"
"2.07936950027943","3366.64208984375","81.9150009155273","1.63928489200771"
"2.08449154160917","3367.28759765625","82.1149978637695","1.64389587007463"
"2.08961335010827","3367.2939453125","82.3150024414063","1.64859485812485"
"2.09467601962388","3367.36401367188","82.5149993896484","1.65325554553419"
"2.09979806095362","3367.42578125","82.7149963378906","1.65787199512124"
"2.10486049763858","3367.81689453125","82.9150009155273","1.66258832905442"
"2.10992293432355","3368.57348632813","83.1149978637695","1.66725809685886"
"2.11504497565329","3367.87475585938","83.3150024414063","1.67195487301797"
"2.12004804052413","3368.34252929688","83.5149993896484","1.6764352330938"
"2.12511047720909","3369.14624023438","83.7149963378906","1.68110930826515"
"2.13017291389406","3369.2607421875","83.9150009155273","1.68570782989264"
"2.1352949552238","3369.28857421875","84.1149978637695","1.69045710936189"
"2.14041699655354","3369.57250976563","84.3150024414063","1.69514410663396"
"2.14541982859373","3368.82397460938","84.5149993896484","1.69969408307225"
"2.15060170739889","3369.728515625","84.7149963378906","1.70429539866745"
"2.15566391125321","3370.0498046875","84.9150009155273","1.70901534147561"
"2.16066697612405","3369.10571289063","85.1149978637695","1.71368953306228"
"2.16578878462315","3370.29345703125","85.3150024414063","1.71830470208079"
"2.17085145413876","3370.771484375","85.5149993896484","1.72293977811933"
"2.17591389082372","3371.11499023438","85.7149963378906","1.72765727620572"
"2.18103593215346","3371.40844726563","85.9150009155273","1.73231540247798"
"2.18609836883843","3371.60961914063","86.1149978637695","1.7369749257341"
"2.19122041016817","3371.18139648438","86.3150024414063","1.74174492713064"
"2.19628284685314","3371.9931640625","86.5149993896484","1.74646731466055"
"2.20134551636875","3371.22216796875","86.7149963378906","1.75106781534851"
"2.20646732486784","3371.72509765625","86.9150009155273","1.75584177486598"
"2.21152999438345","3371.60498046875","87.1149978637695","1.76038360223174"
"2.21659266389906","3372.62890625","87.3150024414063","1.76510354503989"
"2.22165486775339","3372.36010742188","87.5149993896484","1.76974816713482"
"2.22677714191377","3371.61010742188","87.7149963378906","1.7745194490999"
"2.23183934576809","3371.53393554688","87.9150009155273","1.77915801759809"
"2.2369020152837","3371.82763671875","88.1149978637695","1.78378412965685"
"2.24196445196867","3371.9580078125","88.3150024414063","1.78845261689276"
"2.24708649329841","3372.44702148438","88.5149993896484","1.79310247767717"
"2.25214892998338","3372.1611328125","88.7149963378906","1.79772404953837"
"2.25721136666834","3372.291015625","88.9150009155273","1.80243258364499"
"2.26233340799809","3372.97436523438","89.1149978637695","1.80717115290463"
"2.26739607751369","3372.84741210938","89.3150024414063","1.81183265522122"
"2.27251788601279","3372.67016601563","89.5149993896484","1.81643106043339"
"2.27752095088363","3372.54907226563","89.7149963378906","1.82119209785014"
"2.28258338756859","3372.10791015625","89.9150009155273","1.82585336733609"
"2.28776503354311","3372.89111328125","90.1149978637695","1.83061079587787"
"2.29282747022808","3372.28198242188","90.3150024414063","1.83523271698505"
"2.29788990691304","3372.11059570313","90.5149993896484","1.83994835242629"
"2.30295257642865","3372.16040039063","90.7149963378906","1.84455176349729"
"2.30801478028297","3372.45629882813","90.9150009155273","1.84940570034087"
"2.31313705444336","3372.8037109375","91.1149978637695","1.85407069511712"
"2.31819949112833","3371.57470703125","91.3150024414063","1.85875489842147"
"2.32326192781329","3371.20166015625","91.5149993896484","1.86337158083916"
"2.32832436449826","3371.7724609375","91.7149963378906","1.86804553959519"
"2.333446405828","3371.05615234375","91.9150009155273","1.87271100003272"
"2.33850884251297","3370.73828125","92.1149978637695","1.87741534318775"
"2.34363111667335","3370.55297851563","92.3150024414063","1.88207137398422"
"2.3486337158829","3370.22436523438","92.5149993896484","1.88686116598547"
"2.35381559468806","3370.20654296875","92.7149963378906","1.89148855861276"
"2.35887779854238","3369.75708007813","92.9150009155273","1.89617974683642"
"2.36388086341321","3368.59057617188","93.1149978637695","1.90085358917713"
"2.36900290474296","3369.17553710938","93.3150024414063","1.90556689631194"
"2.37406534142792","3368.34521484375","93.5149993896484","1.91022548824549"
"2.37918738275766","3369.181640625","93.7149963378906","1.91509758587927"
"2.38424981944263","3368.95874023438","93.9150009155273","1.91975524649024"
"2.38931248895824","3366.75708007813","94.1149978637695","1.924445386976"
"2.39443453028798","3366.9443359375","94.3150024414063","1.92912120837718"
"2.39949696697295","3366.23901367188","94.5149993896484","1.93380960263312"
"2.40455940365791","3364.85229492188","94.7149963378906","1.93853361997753"
"2.40962184034288","3364.54223632813","94.9150009155273","1.94332783576101"
"2.41468427702785","3363.51318359375","95.1149978637695","1.94791494868696"
"2.41980655118823","3362.95141601563","95.3150024414063","1.95275479927659"
"2.42492835968733","3362.19555664063","95.5149993896484","1.9574339967221"
"2.42999102920294","3361.61206054688","95.7149963378906","1.96217535994947"
"2.43505323305726","3360.24926757813","95.9150009155273","1.96686037816107"
"2.44011590257287","3360.01904296875","96.1149978637695","1.97159918025136"
"2.44517833925784","3358.75390625","96.3150024414063","1.97621597908437"
"2.45030038058758","3358.17578125","96.5149993896484","1.98101415298879"
"2.45536281727254","3357.23510742188","96.7149963378906","1.98565702885389"
"2.46042548678815","3355.95458984375","96.9150009155273","1.99049920774996"
"2.46554729528725","3355.01708984375","97.1149978637695","1.99526082724333"
"2.47060996480286","3352.91577148438","97.3150024414063","2.00003175996244"
"2.47573177330196","3351.96020507813","97.5149993896484","2.00487021356821"
"2.48079444281757","3350.63940429688","97.7149963378906","2.00951262377203"
"2.48585687950253","3349.1708984375","97.9150009155273","2.01434805057943"
"2.49097892083228","3347.99096679688","98.1149978637695","2.01921490952373"
"2.49604135751724","3346.53173828125","98.3150024414063","2.02401261776686"
"2.50110379420221","3344.81591796875","98.5149993896484","2.02869321219623"
"2.50616646371782","3343.64990234375","98.7149963378906","2.03346624039114"
"2.51122890040278","3341.5595703125","98.9150009155273","2.03835708089173"
"2.51635094173253","3339.71704101563","99.1149978637695","2.04314477741718"
"2.52141337841749","3337.4345703125","99.3150024414063","2.04785098321736"
"2.52647581510246","3335.8701171875","99.5149993896484","2.0526428706944"
"2.5315978564322","3334.462890625","99.7149963378906","2.05752160400152"
"2.53666052594781","3332.55126953125","99.9150009155273","2.06229463219643"
"2.54178233444691","3331.22802734375","100.11499786377","2.06717220135033"
"2.54684500396252","3329.1064453125","100.315002441406","2.07197410054505"
"2.55190720781684","3327.09692382813","100.514999389648","2.07676738500595"
"2.55702948197722","3324.29711914063","100.714996337891","2.08161259070039"
"2.56209191866219","3321.37377929688","100.915000915527","2.08644871599972"
"2.56709475070238","3320.21557617188","101.11499786377","2.09118262864649"
"2.57221679203212","3318.25927734375","101.315002441406","2.09614029154181"
"2.57727922871709","3315.4775390625","101.514999389648","2.10099271498621"
"2.58240127004683","3313.17138671875","101.714996337891","2.10592150688171"
"2.58746393956244","3310.48608398438","101.915000915527","2.1107557695359"
"2.59252637624741","3307.77416992188","102.11499786377","2.11559189483523"
"2.59764841757715","3304.99365234375","102.315002441406","2.12055095471442"
"2.60271085426211","3301.8544921875","102.514999389648","2.12550419382751"
"2.60777329094708","3299.45483398438","102.714996337891","2.13027512654662"
"2.61283596046269","3297.3408203125","102.915000915527","2.13510380126536"
"2.61789816431701","3293.73071289063","103.11499786377","2.13999627158046"
"2.6230204384774","3290.64477539063","103.315002441406","2.14499887079"
"2.62814224697649","3287.513671875","103.514999389648","2.1499372087419"
"2.63314531184733","3284.33837890625","103.714996337891","2.15474586002529"
"2.63826735317707","3279.45434570313","103.915000915527","2.1596800070256"
"2.64332978986204","3276.70849609375","104.11499786377","2.16463394463062"
"2.648392226547","3272.70874023438","104.315002441406","2.16950057074428"
"2.65351450070739","3268.6103515625","104.514999389648","2.17449036426842"
"2.65857670456171","3264.56103515625","104.714996337891","2.17934255488217"
"2.66363937407732","3259.14208984375","104.915000915527","2.18434142880142"
"2.66876118257642","3254.52197265625","105.11499786377","2.18934821896255"
"2.67382385209203","3249.70922851563","105.315002441406","2.19420483335853"
"2.67894589342177","3244.72705078125","105.514999389648","2.19912850297987"
"2.68400833010674","3238.27197265625","105.714996337891","2.20399210229516"
"2.68907099962235","3232.83862304688","105.915000915527","2.20884825102985"
"2.69419280812144","3226.98022460938","106.11499786377","2.21379613503814"
"2.69919587299228","3219.27783203125","106.315002441406","2.21860501915216"
"2.70431791432202","3211.38232421875","106.514999389648","2.22352263517678"
"2.70938035100698","3202.28662109375","106.714996337891","2.22847261466086"
"2.71444278769195","3186.79345703125","106.915000915527","2.23336857743561"
"2.71956482902169","3168.35546875","107.11499786377","2.23831017501652"
"2.72462726570666","3154.74365234375","107.315002441406","2.24293721839786"
"2.72968993522227","3144.33959960938","107.514999389648","2.24754097871482"
"2.73481174372137","3135.04833984375","107.714996337891","2.25207977928221"
"2.73987441323698","3121.1865234375","107.915000915527","2.25663813762367"
"2.7449366170913","3104.23754882813","108.11499786377","2.26121488958597"
"2.75005889125168","3077.388671875","108.315002441406","2.26593855768442"
"2.75512132793665","3046.0029296875","108.514999389648","2.27076653391123"
"2.76024336926639","3015.83227539063","108.714996337891","2.27546063251793"
"2.76530580595136","2989.86499023438","108.915000915527","2.27990280836821"
"2.77036824263632","2966.27661132813","109.11499786377","2.28434964083135"
"2.77549028396606","2949.28442382813","109.315002441406","2.28880671784282"
"2.78055295348167","2936.81884765625","109.514999389648","2.2932339925319"
"2.78567476198077","2917.6796875","109.714996337891","2.29784124530852"
"2.79073743149638","2870.77880859375","109.915000915527","2.30258540250361"
"2.7957996353507","2774.69775390625","110.11499786377","2.30930699035525"
"2.80092190951109","2765.1298828125","110.315002441406","2.31383205391467"
"2.80598434619606","2755.26000976563","110.514999389648","2.31859879568219"
"2.81104678288102","2744.2255859375","110.714996337891","2.32332665473223"
"2.81616882421076","2732.369140625","110.915000915527","2.32816068455577"
"2.82123126089573","2721.77954101563","111.11499786377","2.33304547145963"
"2.82635330222547","2711.31176757813","111.315002441406","2.33796681277454"
"2.83141597174108","2702.28881835938","111.514999389648","2.3429102730006"
"2.83647840842605","2692.56494140625","111.714996337891","2.3477531503886"
"2.84160044975579","2682.1103515625","111.915000915527","2.35283328220248"
"2.84666288644075","2672.74853515625","112.11499786377","2.35789455473423"
"2.85172532312572","2660.83837890625","112.315002441406","2.36288271844387"
"2.85684759728611","2652.78955078125","112.514999389648","2.36796541139483"
"2.86185019649565","2643.11206054688","112.714996337891","2.3729857057333"
"2.86703207530081","2633.86303710938","112.915000915527","2.37825745716691"
"2.87209427915514","2625.67993164063","113.11499786377","2.3833429440856"
"2.87715694867074","2617.57373046875","113.315002441406","2.38839560188353"
"2.88227899000049","2609.63940429688","113.514999389648","2.3934724740684"
"2.88734142668545","2601.75439453125","113.714996337891","2.39870161749423"
"2.89240386337042","2592.1943359375","113.915000915527","2.40388442762196"
"2.89746653288603","2580.15893554688","114.11499786377","2.40928772836924"
"2.90252873674035","2563.236328125","114.315002441406","2.41477647796273"
"2.90765101090074","2526.95629882813","114.514999389648","2.42101098410785"
"2.91277281939983","2411.67236328125","114.714996337891","2.43055354803801"
"2.91783548891544","2371.2119140625","114.915000915527","2.4373319465667"
"2.92301713488996","1772.97790527344","115.11499786377","2.46764346957207"
"2.92772217653692","-153.705001831055","115.282997131348","1.9908684771508"