File: Lab2/LabData/Tension/Test Run 1 10-6-2016 2 43 49 PM/DAQ- Crosshead, … - (Timed).csv
"File Path: F:\Test Run 1 10-6-2016 2 43 49 PM\DAQ- Crosshead, … - (Timed).csv
Test: MTS EM Tension (Extensometer) 28
Test Run: Test Run 1
Date: 10/6/2016 1:59:35 PM

"
"Crosshead ","Load ","Time ","Extensometer "
"mm","N","sec","mm"
"0.0037521917874983","40.0766448974609","0.189999997615814","0.00143142312936106"
"0.016319056157954","177.491058349609","0.689999997615814","0.00721950027582352"
"0.0289454801531974","277.192718505859","1.19000005722046","0.0131156912175356"
"0.0416314651374705","349.590026855469","1.69000005722046","0.0193457508430583"
"0.0542578854947351","394.203216552734","2.19000005722046","0.0262686735368334"
"0.0670034278300591","420.900177001953","2.69000005722046","0.0342126222676598"
"0.0796894091763534","439.890472412109","3.19000005722046","0.0430746003985405"
"0.0923753905226476","455.793243408203","3.69000005722046","0.0527945521753281"
"0.105061371868942","470.184020996094","4.19000005722046","0.0627644112682901"
"0.117747353215236","482.430236816406","4.69000005722046","0.0730062674847431"
"0.130433341837488","494.688659667969","5.19000005722046","0.0831234210636467"
"0.143119323183782","506.210205078125","5.69000005722046","0.0932759285205975"
"0.155864865519106","516.686706542969","6.19000005722046","0.103311074781232"
"0.168491285876371","527.959411621094","6.69000005722046","0.113048001367133"
"0.18123681365978","538.172973632813","7.19000005722046","0.122944460599683"
"0.193922809557989","548.926879882813","7.69000005722046","0.132732719066553"
"0.206608790904284","559.1044921875","8.1899995803833","0.142467426485382"
"0.219294772250578","569.177368164063","8.6899995803833","0.152058957610279"
"0.231980753596872","578.299743652344","9.1899995803833","0.161624266183935"
"0.244726281380281","587.447814941406","9.6899995803833","0.171135790878907"
"0.257412291830406","597.628479003906","10.1899995803833","0.180629387614317"
"0.270157819613814","605.821960449219","10.6899995803833","0.190127466339618"
"0.282784225419164","614.406799316406","11.1899995803833","0.199454836547375"
"0.295529782306403","623.412353515625","11.6899995803833","0.208979778108187"
"0.308215763652697","631.701232910156","12.1899995803833","0.218388042412698"
"0.320901744998991","640.29052734375","12.6899995803833","0.227759766858071"
"0.333587726345286","648.549072265625","13.1899995803833","0.237160755204968"
"0.346333254128695","656.9853515625","13.6899995803833","0.246565497945994"
"0.359019235474989","664.974548339844","14.1899995803833","0.256056489888579"
"0.371645670384169","672.924926757813","14.6899995803833","0.265361042693257"
"0.384391227271408","680.255310058594","15.1899995803833","0.27484298334457"
"0.397136755054817","687.57080078125","15.6899995803833","0.284254143480212"
"0.409822736401111","694.987365722656","16.1900005340576","0.293659162707627"
"0.422508717747405","702.958862304688","16.6900005340576","0.30297611374408"
"0.435194699093699","709.787048339844","17.1900005340576","0.312433345243335"
"0.447940226877108","716.29150390625","17.6900005340576","0.321827305015177"
"0.460507086245343","723.713623046875","18.1900005340576","0.331228628056124"
"0.473312189569697","730.670532226563","18.6900005340576","0.340881408192217"
"0.485998170915991","737.314086914063","19.1900005340576","0.350188318407163"
"0.498684181366116","743.812866210938","19.6900005340576","0.359781610313803"
"0.51137013360858","750.642456054688","20.1900005340576","0.369373854482546"
"0.524056144058704","756.21240234375","20.6900005340576","0.379143777536228"
"0.536801700945944","762.880798339844","21.1900005340576","0.387866777600721"
"0.549428106751293","769.087158203125","21.6900005340576","0.397163035813719"
"0.562233210075647","773.891540527344","22.1900005340576","0.407543673645705"
"0.574859615880996","780.906921386719","22.6900005340576","0.418584066210315"
"0.587605172768235","787.617248535156","23.1900005340576","0.427009857958183"
"0.600291125010699","792.480163574219","23.6900005340576","0.43392027146183"
"0.612917530816048","797.235290527344","24.1900005340576","0.443541997810826"
"0.625663087703288","801.106079101563","24.6900005340576","0.454736116807908"
"0.638349039945751","807.741333007813","25.1900005340576","0.466432567918673"
"0.651094596832991","813.48876953125","25.6900005340576","0.476922985399142"
"0.66372100263834","823.351135253906","26.1900005340576","0.485298893181607"
"0.676526105962694","823.390502929688","26.6900005340576","0.491574755869806"
"0.689152569975704","831.859619140625","27.1900005340576","0.500266498420388"
"0.701838580425829","835.027893066406","27.6900005340576","0.512142665684223"
"0.714524532668293","838.996276855469","28.1900005340576","0.523439957760274"
"0.727270089555532","845.16455078125","28.6900005340576","0.534450227860361"
"0.740015646442771","852.003784179688","29.1900005340576","0.545657880138606"
"0.75264205224812","852.963195800781","29.6900005340576","0.553120975382626"
"0.76538760913536","860.750732421875","30.1900005340576","0.556871993467212"
"0.778073561377823","862.891845703125","30.6900005340576","0.567972601857036"
"0.790759571827948","866.831481933594","31.1900005340576","0.57991809444502"
"0.803445524070412","871.298645019531","31.6900005340576","0.590171257499605"
"0.816131534520537","877.74853515625","32.189998626709","0.601738633122295"
"0.828877033200115","880.78564453125","32.689998626709","0.612420204561204"
"0.84156304365024","889.402709960938","33.189998626709","0.618593127001077"
"0.854248995892704","889.789978027344","33.689998626709","0.629819987807423"
"0.866935006342828","893.760131835938","34.189998626709","0.641252787318081"
"0.879680505022407","898.5791015625","34.689998626709","0.648782239295542"
"0.892366515472531","899.802185058594","35.189998626709","0.656319898553193"
"0.904992921277881","904.15966796875","35.689998626709","0.66816428443417"
"0.91773847816512","909.63525390625","36.189998626709","0.680120661854744"
"0.930483976844698","914.77685546875","36.689998626709","0.686470419168472"
"0.943169987294823","915.831298828125","37.189998626709","0.696551811415702"
"0.955855939537287","919.095458984375","37.689998626709","0.708627339918166"
"0.968601496424526","924.358093261719","38.189998626709","0.719757750630379"
"0.981227960437536","926.402954101563","38.689998626709","0.728475686628371"
"0.993973459117115","929.867553710938","39.189998626709","0.740529620088637"
"1.00665946956724","935.609008789063","39.689998626709","0.752550025936216"
"1.01934536360204","938.18701171875","40.189998626709","0.760818074923009"
"1.03209097869694","946.672119140625","40.689998626709","0.764699478168041"
"1.04477698914707","943.597106933594","41.189998626709","0.775906664784998"
"1.05746288318187","946.290283203125","41.689998626709","0.787156342994422"
"1.07014889363199","951.163330078125","42.189998626709","0.797193089965731"
"1.08289439231157","957.754699707031","42.689998626709","0.80465740757063"
"1.09552079811692","954.972900390625","43.189998626709","0.815882463939488"
"1.10826652962714","958.924255371094","43.689998626709","0.827915384434164"
"1.12095254007727","961.411437988281","44.189998626709","0.840368738863617"
"1.13369803875685","966.939636230469","44.689998626709","0.849285104777664"
"1.1463244445622","968.221069335938","45.189998626709","0.855606805998832"
"1.15906994324178","970.720458984375","45.689998626709","0.867756723891944"
"1.1717559536919","974.522705078125","46.189998626709","0.879875209648162"
"1.18444196414202","978.130187988281","46.689998626709","0.891918840352446"
"1.19712797459215","984.7177734375","47.189998626709","0.901208550203592"
"1.20987347327173","981.208740234375","47.689998626709","0.912030809558928"
"1.22255948372185","983.812927246094","48.189998626709","0.924153893720359"
"1.23524537775666","987.141296386719","48.689998626709","0.935878022573888"
"1.24793138820678","992.2451171875","49.189998626709","0.943157414440066"
"1.2606173986569","993.896545410156","49.689998626709","0.94898376846686"
"1.27330340910703","997.59521484375","50.189998626709","0.952599395532161"
"1.28604890778661","994.301818847656","50.689998626709","0.962106394581497"
"1.29867531359196","997.374206542969","51.189998626709","0.97438704688102"
"1.31142081227154","1001.69281005859","51.689998626709","0.98673184402287"
"1.32410682272166","1005.74560546875","52.189998626709","0.999002018943429"
"1.33685232140124","1011.82318115234","52.689998626709","1.0076001053676"
"1.34953833185136","1006.57037353516","53.189998626709","1.01915036793798"
"1.36222434230149","1008.59490966797","53.689998626709","1.03152426891029"
"1.37496984098107","1011.939453125","54.189998626709","1.04394985828549"
"1.38759624678642","1015.94781494141","54.689998626709","1.0557925561443"
"1.40034186188132","1020.68267822266","55.189998626709","1.0641161352396"
"1.41302775591612","1028.07092285156","55.689998626709","1.06799881905317"
"1.42577337101102","1020.05157470703","56.189998626709","1.07959285378456"
"1.43845926504582","1024.44885253906","56.689998626709","1.09181203879416"
"1.45114527549595","1027.33837890625","57.189998626709","1.1042240075767"
"1.46389089059085","1030.21667480469","57.689998626709","1.11657846719027"
"1.4765172963962","1034.44982910156","58.189998626709","1.12692452967167"
"1.48926279507577","1040.07678222656","58.689998626709","1.1338999029249"
"1.5019488055259","1032.60998535156","59.189998626709","1.14631396718323"
"1.51469430420548","1034.68859863281","59.689998626709","1.15878903307021"
"1.52732071001083","1038.00573730469","60.189998626709","1.17104162927717"
"1.54006632510573","1042.15734863281","60.689998626709","1.18323485367"
"1.55275221914053","1046.365234375","61.189998626709","1.1920485412702"
"1.56543822959065","1050.28051757813","61.689998626709","1.19817070662975"
"1.57818372827023","1044.38586425781","62.189998626709","1.20854459237307"
"1.59081013407558","1046.57873535156","62.689998626709","1.21982872951776"
"1.60355574917048","1052.0732421875","63.189998626709","1.22834125068039"
"1.61624175962061","1050.9638671875","63.689998626709","1.24007405247539"
"1.62892765365541","1054.73645019531","64.1900024414063","1.25226529780775"
"1.64161366410553","1057.26818847656","64.6900024414063","1.26384350005537"
"1.65435927920043","1064.04248046875","65.1900024414063","1.27155112568289"
"1.66704528965056","1054.47094726563","65.6900024414063","1.28176005091518"
"1.67967169545591","1058.05102539063","66.1900024414063","1.29351485520601"
"1.69247679878026","1059.32958984375","66.6900024414063","1.30486837588251"
"1.70510320458561","1062.66931152344","67.1900024414063","1.31449231412262"
"1.71784881968051","1066.18322753906","67.6900024414063","1.32665713317692"
"1.73053471371531","1069.39282226563","68.1900024414063","1.33627455215901"
"1.74322072416544","1071.16870117188","68.6900024414063","1.34216446895152"
"1.75590673461556","1066.11071777344","69.1900024414063","1.34795042686164"
"1.76859274506569","1067.23474121094","69.6900024414063","1.3598445802927"
"1.78133824374527","1070.42822265625","70.1900024414063","1.37242919299752"
"1.79396464955062","1073.60034179688","70.6900024414063","1.38467864599079"
"1.80676975287497","1075.59326171875","71.1900024414063","1.39731110539287"
"1.8194557633251","1079.04333496094","71.6900024414063","1.40963506419212"
"1.83208216913044","1081.84448242188","72.1900024414063","1.42123945988715"
"1.84482766781002","1085.94311523438","72.6900024414063","1.42971484456211"
"1.85751367826015","1076.56164550781","73.1900024414063","1.4409979339689"
"1.87025917693973","1079.91369628906","73.6900024414063","1.45329476799816"
"1.88288558274508","1082.41723632813","74.1900024414063","1.4655728591606"
"1.89569068606943","1086.29516601563","74.6900024414063","1.47820147685707"
"1.90837669651955","1087.51940917969","75.1900024414063","1.49063975550234"
"1.92106270696968","1088.33337402344","75.6900024414063","1.50039314758033"
"1.93374860100448","1093.7958984375","76.1900024414063","1.5075042610988"
"1.94643461145461","1092.37731933594","76.6900024414063","1.51285203173757"
"1.95918022654951","1089.47302246094","77.1900024414063","1.52521987911314"
"1.97180663235486","1091.22985839844","77.6900024414063","1.53746246360242"
"1.98461185209453","1093.44274902344","78.1900024414063","1.54988747090101"
"1.99723825789988","1096.02795410156","78.6900024414063","1.56224519014359"
"2.00998387299478","1098.7763671875","79.1900024414063","1.57464505173266"
"2.02266965061426","1101.18493652344","79.6900024414063","1.58693955745548"
"2.03535566106439","1103.00231933594","80.1900024414063","1.59787270240486"
"2.04804167151451","1101.54968261719","80.6900024414063","1.6060242196545"
"2.06072768196464","1101.18176269531","81.1900024414063","1.61133555229753"
"2.07347329705954","1099.01916503906","81.6900024414063","1.62371364422143"
"2.08609970286489","1101.51086425781","82.1900024414063","1.63609161973"
"2.09884508512914","1103.70202636719","82.6900024414063","1.64865714032203"
"2.11153109557927","1105.232421875","83.1900024414063","1.66115921456367"
"2.12421710602939","1107.83984375","83.6900024414063","1.67363078799099"
"2.13696272112429","1110.47436523438","84.1900024414063","1.68384017888457"
"2.14964873157442","1113.13623046875","84.6900024414063","1.69156363699585"
"2.16233474202454","1108.80163574219","85.1900024414063","1.69530173297971"
"2.17502051964402","1118.52453613281","85.6900024414063","1.69756344985217"
"2.18776613473892","1109.02770996094","86.1900024414063","1.70929124578834"
"2.20045214518905","1111.08996582031","86.6900024414063","1.72181078232825"
"2.21313815563917","1112.03308105469","87.1900024414063","1.73417665064335"
"2.2258241660893","1115.73937988281","87.6900024414063","1.74650002736598"
"2.23856954835355","1116.38891601563","88.1900024414063","1.7590174684301"
"2.25125555880368","1117.98217773438","88.6900024414063","1.77152687683702"
"2.2639415692538","1119.64221191406","89.1900024414063","1.7840676009655"
"2.2766871843487","1122.09460449219","89.6900024414063","1.79559260141104"
"2.28937319479883","1127.03918457031","90.1900024414063","1.80441804695874"
"2.30205897241831","1118.34692382813","90.6900024414063","1.81426340714097"
"2.31474498286843","1118.62341308594","91.1900024414063","1.82677747216076"
"2.32743099331856","1120.24963378906","91.6900024414063","1.83923623990268"
"2.34017660841346","1121.60668945313","92.1900024414063","1.85172632336617"
"2.35292222350836","1123.18432617188","92.6900024414063","1.86439801473171"
"2.36554862931371","1125.59741210938","93.1900024414063","1.87680474482477"
"2.37829401157796","1127.54382324219","93.6900024414063","1.8892043735832"
"2.39098002202809","1127.50659179688","94.1900024414063","1.898925867863"
"2.40360642783344","1130.81604003906","94.6900024414063","1.90596503671259"
"2.41635204292834","1135.99841308594","95.1900024414063","1.91090279258788"
"2.42903805337846","1141.02294921875","95.6900024414063","1.91446463577449"
"2.44178343564272","1126.435546875","96.1900024414063","1.92702491767704"
"2.45446944609284","1129.83203125","96.6900024414063","1.93939206656069"
"2.46715545654297","1130.28051757813","97.1900024414063","1.95204350166023"
"2.47984146699309","1132.78686523438","97.6900024414063","1.96450110524893"
"2.49252747744322","1134.22631835938","98.1900024414063","1.97685975581408"
"2.50527309253812","1135.58471679688","98.6900024414063","1.98941421695054"
"2.5179588701576","1136.82299804688","99.1900024414063","2.00163875706494"
"2.53064488060772","1139.90649414063","99.6900024414063","2.0142188295722"
"2.54333089105785","1142.22448730469","100.190002441406","2.02579633332789"
"2.55607650615275","1143.728515625","100.690002441406","2.03518313355744"
"2.5687029119581","1146.84790039063","101.190002441406","2.04185186885297"
"2.581448527053","1135.32421875","101.690002441406","2.05352832563221"
"2.59419390931726","1137.18603515625","102.190002441406","2.06585787236691"
"2.6068203151226","1138.22448730469","102.690002441406","2.07826378755271"
"2.6195659302175","1139.72424316406","103.190002441406","2.09081126376987"
"2.63225194066763","1141.38806152344","103.690002441406","2.10328865796328"
"2.64499732293189","1142.89855957031","104.190002441406","2.11605010554194"
"2.65762396156788","1145.54638671875","104.690002441406","2.12831073440611"
"2.67036934383214","1145.59545898438","105.190002441406","2.13844864629209"
"2.68305535428226","1147.67443847656","105.690002441406","2.14650901034474"
"2.69574136473238","1150.38000488281","106.190002441406","2.15167389251292"
"2.70848697982728","1156.0166015625","106.690002441406","2.15450651012361"
"2.72111338563263","1143.53381347656","107.190002441406","2.16412986628711"
"2.73385876789689","1145.35314941406","107.690002441406","2.17660935595632"
"2.74654477834702","1146.5234375","108.190002441406","2.18902085907757"
"2.75929039344192","1146.84057617188","108.690002441406","2.20158719457686"
"2.77191679924726","1148.92541503906","109.190002441406","2.21408111974597"
"2.78466241434217","1150.49462890625","109.690002441406","2.22655618563294"
"2.79740779660642","1152.68249511719","110.190002441406","2.23921774886549"
"2.80997483059764","1153.77905273438","110.690002441406","2.2514914162457"
"2.82277981750667","1156.56262207031","111.190002441406","2.26421770639718"
"2.8354658279568","1156.92944335938","111.690002441406","2.2767037153244"
"2.84815183840692","1158.00122070313","112.190002441406","2.2876204457134"
"2.86083784885705","1162.13635253906","112.690002441406","2.29671504348516"
"2.8735832311213","1151.99584960938","113.190002441406","2.30749999172986"
"2.88626924157143","1152.12707519531","113.690002441406","2.31981719844043"
"2.89889564737678","1154.48999023438","114.190002441406","2.33218725770712"
"2.91170086711645","1154.58056640625","114.690002441406","2.34489911235869"
"2.9243272729218","1156.15844726563","115.190002441406","2.35746731050313"
"2.93707265518606","1158.01818847656","115.690002441406","2.37010791897774"
"2.94969906099141","1159.36560058594","116.190002441406","2.38261744379997"
"2.96244467608631","1161.18872070313","116.690002441406","2.3951914627105"
"2.97513068653643","1161.7275390625","117.190002441406","2.40576174110174"
"2.98787630163133","1163.64685058594","117.690002441406","2.41479277610779"
"3.0005625449121","1166.16455078125","118.190002441406","2.42251995950937"
"3.01324808970094","1169.28601074219","118.690002441406","2.42933887057006"
"3.02599393762648","1158.40026855469","119.190002441406","2.44049308821559"
"3.03862034343183","1160.13195800781","119.690002441406","2.45282775722444"
"3.05136595852673","1160.63122558594","120.190002441406","2.46536708436906"
"3.06405196897686","1162.04846191406","120.690002441406","2.47788242995739"
"3.07673797942698","1163.47265625","121.190002441406","2.49026785604656"
"3.08948336169124","1165.3916015625","121.690002441406","2.50278529711068"
"3.10210976749659","1166.1396484375","122.190002441406","2.51530995592475"
"3.11485538259149","1167.30603027344","122.690002441406","2.52807699143887"
"3.12754139304161","1168.73596191406","123.190002441406","2.54065287299454"
"3.14022740349174","1170.16430664063","123.690002441406","2.55328346975148"
"3.15291341394186","1170.77758789063","124.190002441406","2.56571429781616"
"3.16565879620612","1172.18737792969","124.690002441406","2.57754139602184"
"3.17834480665624","1174.34020996094","125.190002441406","2.58758524432778"
"3.19103081710637","1173.14343261719","125.690002441406","2.59593781083822"
"3.20377643220127","1177.85864257813","126.190002441406","2.60154693387449"
"3.21646220982075","1164.74890136719","126.690002441406","2.61360709555447"
"3.22914822027087","1167.38549804688","127.190002441406","2.62611010111868"
"3.241834230721","1168.6357421875","127.690002441406","2.63862940482795"
"3.2545798458159","1169.91943359375","128.190002441406","2.65116058290005"
"3.26726585626602","1170.84692382813","128.690002441406","2.66379886306822"
"3.27995186671615","1171.81750488281","129.190002441406","2.67635984346271"
"3.2926972489804","1173.30590820313","129.690002441406","2.68876599147916"
"3.30532365478575","1175.27258300781","130.190002441406","2.70148436538875"
"3.31806926988065","1176.90563964844","130.690002441406","2.71365302614868"
"3.33075528033078","1176.02819824219","131.190002441406","2.72392388433218"
"3.3434412907809","1177.26342773438","131.690002441406","2.73259845562279"
"3.35612730123103","1178.38305664063","132.190002441406","2.73951701819897"
"3.36893228814006","1178.02990722656","132.690002441406","2.74444208480418"
"3.38155869394541","1172.22351074219","133.190002441406","2.75573530234396"
"3.39424470439553","1174.23937988281","133.690002441406","2.76786391623318"
"3.40704969130456","1174.57275390625","134.190002441406","2.78035155497491"
"3.41967632994056","1175.23107910156","134.690002441406","2.79270717874169"
"3.43236210756004","1176.51794433594","135.190002441406","2.80502322129905"
"3.44504811801016","1177.76184082031","135.690002441406","2.81762471422553"
"3.45779373310506","1179.59899902344","136.190002441406","2.83010746352375"
"3.47047974355519","1180.69750976563","136.690002441406","2.84256250597537"
"3.48316575400531","1180.95349121094","137.190002441406","2.85500544123352"
"3.49585176445544","1182.45788574219","137.690002441406","2.86749307997525"
"3.50859714671969","1183.03503417969","138.190002441406","2.88011832162738"
"3.52128315716982","1183.99279785156","138.690002441406","2.89245042949915"
"3.53396916761994","1184.72973632813","139.190002441406","2.90481955744326"
"3.54665517807007","1185.92028808594","139.690002441406","2.9156724922359"
"3.55934118852019","1188.92260742188","140.190002441406","2.92537431232631"
"3.57208657078445","1187.58044433594","140.690002441406","2.93406029231846"
"3.5847129765898","1178.73205566406","141.190002441406","2.94554024003446"
"3.5974585916847","1179.56652832031","141.690002441406","2.95792031101882"
"3.6102042067796","1181.76293945313","142.190002441406","2.97028664499521"
"3.62283061258495","1180.65612792969","142.690002441406","2.98281968571246"
"3.63551662303507","1182.48693847656","143.190002441406","2.99541791900992"
"3.64826200529933","1183.23986816406","143.690002441406","3.00783780403435"
"3.66094801574945","1184.71936035156","144.190002441406","3.02058621309698"
"3.67363402619958","1186.17932128906","144.690002441406","3.03317233920097"
"3.68637964129448","1187.31921386719","145.190002441406","3.04591120220721"
"3.6990656517446","1187.8935546875","145.690002441406","3.05831013247371"
"3.71175142936409","1187.53295898438","146.190002441406","3.06914700195193"
"3.72443743981421","1187.78332519531","146.690002441406","3.07808700017631"
"3.73712345026433","1188.64172363281","147.190002441406","3.0851885676384"
"3.74986906535923","1190.56982421875","147.690002441406","3.09076881967485"
"3.76255507580936","1194.03210449219","148.190002441406","3.09484452009201"
"3.77530045807362","1194.55480957031","148.690002441406","3.10132233425975"
"3.78792686387897","1184.06909179688","149.190002441406","3.11321718618274"
"3.80067247897387","1185.79235839844","149.690002441406","3.12564219348133"
"3.81341809406877","1187.48999023438","150.190002441406","3.13812331296504"
"3.82604449987412","1186.96044921875","150.690002441406","3.15063842572272"
"3.83879011496902","1188.18823242188","151.190002441406","3.16331069916487"
"3.85141652077436","1188.45007324219","151.690002441406","3.17593151703477"
"3.8642215076834","1189.33447265625","152.190002441406","3.1885914504528"
"3.87684791348875","1190.62072753906","152.690002441406","3.20108095183969"
"3.88959352858365","1191.26916503906","153.190002441406","3.21388454176486"
"3.90227953903377","1192.09936523438","153.690002441406","3.22645949199796"
"3.91496578231454","1192.16979980469","154.190002441406","3.23901162482798"
"3.92765132710338","1193.78564453125","154.690002441406","3.25162941589952"
"3.9403373375535","1194.99560546875","155.190002441406","3.26417060568929"
"3.9530829526484","1196.47668457031","155.690002441406","3.27684660442173"
"3.96576896309853","1196.78930664063","156.190002441406","3.28934518620372"
"3.97851457819343","1196.66223144531","156.690002441406","3.30112036317587"
"3.99114098399878","1198.11022949219","157.190002441406","3.31123196519911"
"4.0038269944489","1197.91369628906","157.690002441406","3.31986090168357"
"4.0165726095438","1201.89575195313","158.190002441406","3.32764605991542"
"4.02919901534915","1189.74438476563","158.690002441406","3.33912926726043"
"4.04194463044405","1191.33276367188","159.190002441406","3.35176661610603"
"4.05463017523289","1192.68054199219","159.690002441406","3.36427194997668"
"4.06737625598907","1192.13317871094","160.190002441406","3.37691279128194"
"4.08000219613314","1193.35314941406","160.690002441406","3.38956876657903"
"4.09274827688932","1193.11047363281","161.190002441406","3.40210041031241"
"4.10543382167816","1194.9560546875","161.690002441406","3.41476523317397"
"4.11811983212829","1195.18139648438","162.190002441406","3.42738442122936"
"4.13086544722319","1195.88952636719","162.690002441406","3.44007392413914"
"4.14355145767331","1196.00512695313","163.190002441406","3.45272128470242"
"4.15623746812344","1197.19494628906","163.690002441406","3.46531043760479"
"4.16892347857356","1198.2666015625","164.190002441406","3.477499820292"
"4.18166862800717","1198.86291503906","164.690002441406","3.48836625926197"
"4.19429549947381","1200.25891113281","165.190002441406","3.49817355163395"
"4.20704064890742","1200.64831542969","165.690002441406","3.50654846988618"
"4.21978672966361","1203.25598144531","166.190002441406","3.51468985900283"
"4.23241266980767","1202.81628417969","166.690002441406","3.52235673926771"
"4.24515828490257","1194.74841308594","167.190002441406","3.53368953801692"
"4.2578442953527","1196.28674316406","167.690002441406","3.54614108800888"
"4.27053030580282","1197.59338378906","168.190002441406","3.55856399983168"
"4.28321631625295","1197.76477050781","168.690002441406","3.57099645771086"
"4.29596193134785","1198.44921875","169.190002441406","3.58374090865254"
"4.30864747613668","1198.9677734375","169.690002441406","3.59640945680439"
"4.3213339522481","1199.4296875","170.190002441406","3.60881024971604"
"4.33407910168171","1199.69689941406","170.690002441406","3.62147414125502"
"4.34676557779312","1199.94165039063","171.190002441406","3.63408657722175"
"4.35945112258196","1201.3134765625","171.690002441406","3.64668527618051"
"4.37213759869337","1201.51550292969","172.190002441406","3.65919852629304"
"4.38488274812698","1202.36743164063","172.690002441406","3.67178837768734"
"4.39750915393233","1203.44323730469","173.190002441406","3.68420011363924"
"4.41019516438246","1203.84777832031","173.690002441406","3.69676109403372"
"4.42300038412213","1203.13598632813","174.190002441406","3.70833603665233"
"4.43562678992748","1205.52612304688","174.690002441406","3.71720176190138"
"4.44837240502238","1205.30236816406","175.190002441406","3.72943934053183"
"4.46105794981122","1206.42895507813","175.690002441406","3.74186341650784"
"4.47374442592263","1206.29479980469","176.190002441406","3.75335081480443"
"4.48642997071147","1208.384765625","176.690002441406","3.76419187523425"
"4.49917605146766","1208.57849121094","177.190002441406","3.77494818530977"
"4.51186159625649","1199.90771484375","177.690002441406","3.78711638040841"
"4.52454760670662","1199.51879882813","178.190002441406","3.79978655837476"
"4.53729322180152","1201.29846191406","178.690002441406","3.81230958737433"
"4.54997923225164","1200.89892578125","179.190002441406","3.82500584237278"
"4.56266524270177","1201.57287597656","179.690002441406","3.83744132705033"
"4.57535125315189","1201.85241699219","180.190002441406","3.85006959550083"
"4.58809640258551","1201.9013671875","180.690002441406","3.86258587241173"
"4.60078287869692","1202.91638183594","181.190002441406","3.87526955455542"
"4.61346842348576","1204.00988769531","181.690002441406","3.88792878948152"
"4.62621450424194","1204.42919921875","182.190002441406","3.90068651176989"
"4.63884044438601","1205.21203613281","182.690002441406","3.91313061118126"
"4.65158652514219","1206.54248046875","183.190002441406","3.92576400190592"
"4.66421293094754","1206.85827636719","183.690002441406","3.93830239772797"
"4.67695808038116","1207.54357910156","184.190002441406","3.95086780190468"
"4.68964455649257","1208.66760253906","184.690002441406","3.96262016147375"
"4.70238970592618","1208.06506347656","185.190002441406","3.97335225716233"
"4.71501657739282","1207.80078125","185.690002441406","3.98237491026521"
"4.72776172682643","1208.38073730469","186.190002441406","3.99015285074711"
"4.74044773727655","1208.88244628906","186.690002441406","3.99639317765832"
"4.75313374772668","1211.20678710938","187.190002441406","4.0007415227592"
"4.7658197581768","1212.76879882813","187.690002441406","4.00554807856679"
"4.77850576862693","1213.66857910156","188.190002441406","4.01226058602333"
"4.7913109883666","1206.65686035156","188.690002441406","4.02268534526229"
"4.80393692851067","1202.84326171875","189.190002441406","4.03500394895673"
"4.81662340462208","1203.78979492188","189.690002441406","4.04757773503661"
"4.82936855405569","1204.58056640625","190.190002441406","4.0601147338748"
"4.8420550301671","1205.09020996094","190.690002441406","4.07266896218061"
"4.85474057495594","1206.70666503906","191.190002441406","4.08528139814734"
"4.86742705106735","1206.64709472656","191.690002441406","4.0978635661304"
"4.88017220050097","1207.53588867188","192.190002441406","4.1105062700808"
"4.89285821095109","1207.29992675781","192.690002441406","4.12305817008018"
"4.90554422140121","1207.57458496094","193.190002441406","4.13580983877182"
"4.91823023185134","1207.32165527344","193.690002441406","4.14840038865805"
"4.93097584694624","1206.8740234375","194.190002441406","4.16118185967207"
"4.94366185739636","1207.72863769531","194.690002441406","4.17376402765512"
"4.9563474021852","1207.94641113281","195.190002441406","4.18643653392792"
"4.96909348294139","1208.69067382813","195.690002441406","4.19904617592692"
"4.98177902773023","1209.39965820313","196.190002441406","4.21178108081222"
"4.99452510848641","1208.79968261719","196.690002441406","4.2245383374393"
"5.00715104863048","1210.05163574219","197.190002441406","4.23709768801928"
"5.01989666372538","1209.50207519531","197.690002441406","4.24988893792033"
"5.0325826741755","1210.37280273438","198.190002441406","4.26251301541924"
"5.04526868462563","1210.8193359375","198.690002441406","4.27521346136928"
"5.05795469507575","1212.25756835938","199.190002441406","4.28784731775522"
"5.07064070552588","1212.17138671875","199.690002441406","4.30047046393156"
"5.08338585495949","1213.0927734375","200.190002441406","4.3132808059454"
"5.09601272642612","1213.88854980469","200.690002441406","4.32575074955821"
"5.10881748050451","1213.4990234375","201.190002441406","4.33856900781393"
"5.12144435197115","1214.5419921875","201.690002441406","4.35089273378253"
"5.13418950140476","1214.34436035156","202.190002441406","4.36238059774041"
"5.14687597751617","1215.38439941406","202.690002441406","4.37280535697937"
"5.15956152230501","1215.35485839844","203.190002441406","4.3822880834341"
"5.17230713739991","1218.732421875","203.690002441406","4.39095357432961"
"5.18493354320526","1218.69787597656","204.190002441406","4.39906725659966"
"5.19773876294494","1219.00622558594","204.690002441406","4.40334063023329"
"5.21030556410551","1210.00939941406","205.190002441406","4.41286107525229"
"5.22305117920041","1208.49462890625","205.690002441406","4.42536314949393"
"5.23579632863402","1209.97265625","206.190002441406","4.4378824532032"
"5.24842320010066","1209.72387695313","206.690002441406","4.45047812536359"
"5.26122795417905","1210.76782226563","207.190002441406","4.4631389901042"
"5.27391443029046","1211.35168457031","207.690002441406","4.47586504742503"
"5.2865999750793","1211.45715332031","208.190002441406","4.48846118524671"
"5.29922638088465","1211.97741699219","208.690002441406","4.50102845206857"
"5.31197199597955","1211.86975097656","209.190002441406","4.51380107551813"
"5.32465800642967","1212.93615722656","209.690002441406","4.52633900567889"
"5.3373440168798","1213.48095703125","210.190002441406","4.53892024233937"
"5.3500896319747","1214.14526367188","210.690002441406","4.55176597461104"
"5.36277517676353","1214.20263671875","211.190002441406","4.56432439386845"
"5.37546165287495","1215.69079589844","211.690002441406","4.57704300060868"
"5.38814719766378","1214.4560546875","212.190002441406","4.58941794931889"
"5.40089327841997","1213.90405273438","212.690002441406","4.60187206044793"
"5.41351921856403","1210.31665039063","213.190002441406","4.61443699896336"
"5.42626529932022","1209.55590820313","213.690002441406","4.62703732773662"
"5.43901044875383","1209.24890136719","214.190002441406","4.6397065743804"
"5.45163685455918","1209.80517578125","214.690002441406","4.65238001197577"
"5.46438246965408","1209.50964355469","215.190002441406","4.66506974771619"
"5.47706848010421","1209.82983398438","215.690002441406","4.67774970456958"
"5.48975449055433","1210.24645996094","216.190002441406","4.69039566814899"
"5.50244050100446","1211.96142578125","216.690002441406","4.70299040898681"
"5.51518565043807","1211.67053222656","217.190002441406","4.71561029553413"
"5.52787212654948","1211.91723632813","217.690002441406","4.72825905308127"
"5.54055767133832","1211.93078613281","218.190002441406","4.7410842962563"
"5.55330375209451","1212.7255859375","218.690002441406","4.75395331159234"
"5.56598929688334","1212.20056152344","219.190002441406","4.76652197539806"
"5.57867530733347","1213.10400390625","219.690002441406","4.77924523875117"
"5.59136131778359","1213.1494140625","220.190002441406","4.79188980534673"
"5.60410693287849","1213.31591796875","220.690002441406","4.8044784925878"
"5.61679294332862","1213.60656738281","221.190002441406","4.81721991673112"
"5.62947895377874","1214.16833496094","221.690002441406","4.8298854380846"
"5.64216496422887","1215.10607910156","222.190002441406","4.84272837638855"
"5.65485097467899","1214.80590820313","222.690002441406","4.85545722767711"
"5.66759612411261","1216.20776367188","223.190002441406","4.86817816272378"
"5.68028260022402","1216.31555175781","223.690002441406","4.88084554672241"
"5.69296814501286","1216.54760742188","224.190002441406","4.89338114857674"
"5.70565462112427","1216.25634765625","224.690002441406","4.90616168826818"
"5.71839977055788","1216.57922363281","225.190002441406","4.91876993328333"
"5.73108578100801","1217.984375","225.690002441406","4.9315788783133"
"5.74377225711942","1217.31921386719","226.190002441406","4.94437385350466"
"5.75645780190825","1217.93420410156","226.690002441406","4.95700072497129"
"5.76920388266444","1217.94030761719","227.190002441406","4.96975891292095"
"5.78188942745328","1218.88391113281","227.690002441406","4.98228007927537"
"5.7945754379034","1218.18017578125","228.190002441406","4.99489437788725"
"5.8073210529983","1218.89953613281","228.690002441406","5.00765768811107"
"5.81994745880365","1219.93103027344","229.190002441406","5.020288284868"
"5.83269307389855","1219.95544433594","229.690002441406","5.03299478441477"
"5.84537908434868","1215.91857910156","230.190002441406","5.04587171599269"
"5.85806462913752","1212.19409179688","230.690002441406","5.0587453879416"
"5.87075110524893","1211.99340820313","231.190002441406","5.0713405944407"
"5.88343665003777","1211.91625976563","231.690002441406","5.08407782763243"
"5.89618273079395","1212.25524902344","232.190002441406","5.09674474596977"
"5.90886827558279","1211.75244140625","232.690002441406","5.10952109470963"
"5.92161389067769","1211.76928710938","233.190002441406","5.12220058590174"
"5.93429990112782","1212.26513671875","233.690002441406","5.13490382581949"
"5.94698591157794","1212.158203125","234.190002441406","5.14762010425329"
"5.95967192202806","1212.58825683594","234.690002441406","5.16031682491302"
"5.97235793247819","1213.07299804688","235.190002441406","5.17302425578237"
"5.98504394292831","1213.11889648438","235.690002441406","5.18560176715255"
"5.99772995337844","1213.17700195313","236.190002441406","5.19835017621517"
"6.01053470745683","1213.32995605469","236.690002441406","5.21110370755196"
"6.02316157892346","1213.03857421875","237.190002441406","5.22375386208296"
"6.0358471237123","1213.28186035156","237.690002441406","5.23655535653234"
"6.04859320446849","1214.0244140625","238.190002441406","5.24933030828834"
"6.06127874925733","1213.43371582031","238.690002441406","5.26203215122223"
"6.07396475970745","1213.99255371094","239.190002441406","5.27476100251079"
"6.08665077015758","1214.00305175781","239.690002441406","5.28745399788022"
"6.09939638525248","1214.44714355469","240.190002441406","5.30022103339434"
"6.11202279105783","1214.61303710938","240.690002441406","5.31291170045733"
"6.12476840615273","1214.84436035156","241.190002441406","5.32568199560046"
"6.13745441660285","1214.94958496094","241.690002441406","5.33841317519546"
"6.15014042705297","1214.33056640625","242.190002441406","5.35119650885463"
"6.16282597184181","1215.33728027344","242.690002441406","5.36385597661138"
"6.175572052598","1214.92370605469","243.190002441406","5.37672732025385"
"6.18825759738684","1215.28625488281","243.690002441406","5.38935186341405"
"6.20094407349825","1214.19921875","244.190002441406","5.402154289186"
"6.21368922293186","1214.07238769531","244.690002441406","5.4149585776031"
"6.22631562873721","1213.79968261719","245.190002441406","5.4275756701827"
"6.23906124383211","1213.48571777344","245.690002441406","5.44051034376025"
"6.25174725428224","1212.6416015625","246.190002441406","5.45322941616178"
"6.26443326473236","1212.2431640625","246.690002441406","5.4658823646605"
"6.27711927518249","1212.09936523438","247.190002441406","5.47866383567452"
"6.2898644246161","1211.5341796875","247.690002441406","5.49140898510814"
"6.30261050537229","1211.31311035156","248.190002441406","5.50429010763764"
"6.31523644551635","1211.3251953125","248.690002441406","5.51693420857191"
"6.32798252627254","1210.94274902344","249.190002441406","5.52978599444032"
"6.3406084664166","1211.08972167969","249.690002441406","5.54234394803643"
"6.3533540815115","1210.552734375","250.190002441406","5.55506907403469"
"6.36604009196162","1210.56652832031","250.690002441406","5.56773599237204"
"6.37878570705652","1209.66357421875","251.190002441406","5.58046065270901"
"6.39147171750665","1209.95190429688","251.690002441406","5.59336459264159"
"6.40415772795677","1209.64184570313","252.190002441406","5.60605060309172"
"6.41690287739038","1209.98474121094","252.690002441406","5.618907045573"
"6.42952974885702","1209.98620605469","253.190002441406","5.63145475462079"
"6.44227489829063","1208.900390625","253.690002441406","5.64421759918332"
"6.45496137440205","1209.29089355469","254.190002441406","5.65700326114893"
"6.46764691919088","1207.60363769531","254.690002441406","5.6695593520999"
"6.48039299994707","1208.14196777344","255.190002441406","5.68251824006438"
"6.49307854473591","1206.99694824219","255.690002441406","5.69529365748167"
"6.50582415983081","1207.48266601563","256.190002441406","5.70810027420521"
"6.51839096099138","1206.92822265625","256.690002441406","5.72063494473696"
"6.53119618073106","1205.57312011719","257.190002441406","5.7334597222507"
"6.54388219118118","1206.05432128906","257.690002441406","5.74605586007237"
"6.55656820163131","1205.57678222656","258.190002441406","5.75874745845795"
"6.56925374642015","1204.74829101563","258.690002441406","5.77147398144007"
"6.58199982717633","1203.70642089844","259.190002441406","5.78436674550176"
"6.59468537196517","1203.74829101563","259.690002441406","5.79717429354787"
"6.60731224343181","1202.83813476563","260.190002441406","5.80995297059417"
"6.62011699751019","1202.45629882813","260.690002441406","5.8226608671248"
"6.63274386897683","1201.49475097656","261.190002441406","5.83537295460701"
"6.64548901841044","1200.2109375","261.690002441406","5.84814278408885"
"6.65817502886057","1199.86743164063","262.190002441406","5.86094660684466"
"6.67086103931069","1199.49340820313","262.690002441406","5.87357860058546"
"6.68354704976082","1199.01013183594","263.190002441406","5.88644156232476"
"6.69623306021094","1197.54028320313","263.690002441406","5.89920300990343"
"6.70897867530584","1197.11047363281","264.190002441406","5.91207249090075"
"6.72160461544991","1196.46948242188","264.690002441406","5.9247212484479"
"6.73441030085087","1195.40319824219","265.190002441406","5.93757629394531"
"6.74703624099493","1194.89636230469","265.690002441406","5.95025112852454"
"6.75972271710634","1193.07983398438","266.190002441406","5.96296833828092"
"6.77246786653996","1192.37097167969","266.690002441406","5.97585551440716"
"6.78521348163486","1192.47644042969","267.190002441406","5.98370982334018"
"6.79789949208498","1193.81408691406","267.690002441406","5.98373496904969"
"6.81052589789033","1191.61547851563","268.190002441406","5.98370563238859"
"6.82327197864652","1190.78198242188","268.690002441406","5.9837531298399"
"6.83595752343535","1189.32238769531","269.190002441406","5.98374800756574"
"6.84870313853025","1187.98071289063","269.690002441406","5.9838043525815"
"6.86138914898038","1187.06372070313","270.190002441406","5.98381087183952"
"6.8740751594305","1186.1513671875","270.690002441406","5.98382437601686"
"6.88676116988063","1184.96337890625","271.190002441406","5.98383089527488"
"6.89950678497553","1183.50390625","271.690002441406","5.98387187346816"
"6.91219232976437","1182.02917480469","272.190002441406","5.98388724029064"
"6.92487880587578","1180.23608398438","272.690002441406","5.98383322358131"
"6.93762395530939","1178.52709960938","273.190002441406","5.98391052335501"
"6.95025082677603","1177.63391113281","273.690002441406","5.98391983658075"
"6.96299597620964","1175.47448730469","274.190002441406","5.98394172266126"
"6.97568245232105","1174.47302246094","274.690002441406","5.983826238662"
"6.98842760175467","1173.14672851563","275.190002441406","5.98392682150006"
"7.00111361220479","1172.2060546875","275.690002441406","5.98392216488719"
"7.01379962265491","1169.4150390625","276.190002441406","5.98390772938728"
"7.02654523774982","1167.85229492188","276.690002441406","5.98400505259633"
"7.03917164355516","1166.60852050781","277.190002441406","5.98401110619307"
"7.05185765400529","1165.03125","277.690002441406","5.98404137417674"
"7.06454319879413","1162.65124511719","278.190002441406","5.98394405096769"
"7.07728927955031","1161.14624023438","278.690002441406","5.98406745120883"
"7.08997482433915","1159.08813476563","279.190002441406","5.98404696211219"
"7.10266130045056","1157.6416015625","279.690002441406","5.98396454006433"
"7.11540644988418","1155.953125","280.190002441406","5.9840097092092"
"7.12803332135081","1153.87646484375","280.690002441406","5.9839989989996"
"7.14077847078443","1152.349609375","281.190002441406","5.98405906930566"
"7.15346448123455","1149.53747558594","281.690002441406","5.9839989989996"
"7.16615049168468","1147.97253417969","282.190002441406","5.98403299227357"
"7.1788365021348","1145.58581542969","282.690002441406","5.98401436582208"
"7.19158165156841","1143.1533203125","283.190002441406","5.98403858020902"
"7.20426812767982","1141.03283691406","283.690002441406","5.98413217812777"
"7.21695367246866","1139.12219238281","284.190002441406","5.98408095538616"
"7.22969975322485","1136.68103027344","284.690002441406","5.98415220156312"
"7.24232569336891","1133.97595214844","285.190002441406","5.9842262417078"
"7.2550717741251","1131.40502929688","285.690002441406","5.98416198045015"
"7.26775731891394","1128.79150390625","286.190002441406","5.98408980295062"
"7.28050293400884","1126.74914550781","286.690002441406","5.9841787442565"
"7.29312933981419","1124.45617675781","287.190002441406","5.98419643938541"
"7.30587495490909","1121.54296875","287.690002441406","5.98419783636928"
"7.31862057000399","1118.39953613281","288.190002441406","5.98428491503"
"7.33124697580934","1115.92163085938","288.690002441406","5.98424347117543"
"7.34399212524295","1112.98498535156","289.190002441406","5.98431751132011"
"7.35667860135436","1109.44152832031","289.690002441406","5.98434917628765"
"7.36942375078797","1106.67211914063","290.190002441406","5.9842960909009"
"7.38205062225461","1104.82202148438","290.690002441406","5.98425138741732"
"7.39479577168822","1101.38830566406","291.190002441406","5.98412938416004"
"7.40748178213835","1099.09814453125","291.690002441406","5.98423648625612"
"7.42016779258847","1096.0615234375","292.190002441406","5.98431099206209"
"7.43291340768337","1092.50927734375","292.690002441406","5.98424253985286"
"7.44553981348872","1090.08618164063","293.190002441406","5.98424021154642"
"7.45828542858362","1086.82312011719","293.690002441406","5.98420621827245"
"7.47097143903375","1083.97290039063","294.190002441406","5.98426349461079"
"7.48371705412865","1081.12170410156","294.690002441406","5.9841200709343"
"7.49634299427271","1077.36193847656","295.190002441406","5.98414894193411"
"7.5090890750289","1073.8525390625","295.690002441406","5.98410703241825"
"7.52183422446251","1070.36608886719","296.190002441406","5.98412984982133"
"7.53446109592915","1066.82421875","296.690002441406","5.98412984982133"
"7.54720624536276","1063.32556152344","297.190002441406","5.98425138741732"
"7.55989225581288","1059.20629882813","297.690002441406","5.98407816141844"
"7.57257826626301","1056.62145996094","298.190002441406","5.98412146791816"
"7.58526427671313","1052.8212890625","298.690002441406","5.98416570574045"
"7.59800989180803","1048.19116210938","299.190002441406","5.98413730040193"
"7.61069590225816","1045.14465332031","299.690002441406","5.98421553149819"
"7.623381447047","1040.62976074219","300.190002441406","5.9842593036592"
"7.63612752780318","1036.67431640625","300.690002441406","5.98426535725594"
"7.64875346794724","1033.17431640625","301.190002441406","5.98428165540099"
"7.66149954870343","1027.92272949219","301.690002441406","5.98429329693317"
"7.67418509349227","1024.77294921875","302.190002441406","5.98430400714278"
"7.68687110394239","1020.09075927734","302.690002441406","5.98433054983616"
"7.69961671903729","1016.10754394531","303.190002441406","5.98431564867496"
"7.71230272948742","1010.96899414063","303.690002441406","5.98429515957832"
"7.72498873993754","1007.30316162109","304.190002441406","5.98437944427133"
"7.73761514574289","1002.56829833984","304.690002441406","5.98446186631918"
"7.75041989982128","997.1630859375","305.190002441406","5.98438596352935"
"7.76304677128792","993.407287597656","305.690002441406","5.98438596352935"
"7.77579192072153","988.416809082031","306.190002441406","5.9843729250133"
"7.78847839683294","983.657592773438","306.690002441406","5.98446605727077"
"7.80122354626656","979.012817382813","307.190002441406","5.98444137722254"
"7.81391002237797","973.3154296875","307.690002441406","5.98456896841526"
"7.82653596252203","967.644165039063","308.190002441406","5.98454102873802"
"7.83934071660042","963.242065429688","308.690002441406","5.98460156470537"
"7.85196758806705","957.829956054688","309.190002441406","5.98455965518951"
"7.86471273750067","952.944580078125","309.690002441406","5.98455965518951"
"7.87739921361208","947.57861328125","310.190002441406","5.98454615101218"
"7.89014436304569","942.040588378906","310.690002441406","5.98458852618933"
"7.9028308391571","935.957885742188","311.190002441406","5.98456244915724"
"7.91551731526852","930.825012207031","311.690002441406","5.98452566191554"
"7.92820286005735","924.92626953125","312.190002441406","5.98450656980276"
"7.94088933616877","918.869079589844","312.690002441406","5.98446791991591"
"7.95363448560238","914.093017578125","313.190002441406","5.98444091156125"
"7.96632003039122","907.144897460938","313.690002441406","5.98443811759353"
"7.97900650650263","901.70458984375","314.190002441406","5.98446233198047"
"7.99169205129147","895.719055175781","314.690002441406","5.98444556817412"
"8.00443720072508","888.6826171875","315.190002441406","5.98445441573858"
"8.01712460815907","882.610107421875","315.690002441406","5.98444370552897"
"8.0298101529479","876.153076171875","316.190002441406","5.98452473059297"
"8.04255530238152","869.863220214844","316.690002441406","5.98460389301181"
"8.05524177849293","862.175659179688","317.190002441406","5.98446698859334"
"8.06792732328177","855.012451171875","317.690002441406","5.98446233198047"
"8.0806128680706","848.705444335938","318.190002441406","5.98447117954493"
"8.09335894882679","841.1865234375","318.690002441406","5.98452892154455"
"8.10604449361563","833.692504882813","319.190002441406","5.98453031852841"
"8.11873096972704","826.33544921875","319.690002441406","5.98463090136647"
"8.13141651451588","817.169738769531","320.190002441406","5.98456896841526"
"8.14410299062729","808.954162597656","320.690002441406","5.9846006333828"
"8.1568481400609","797.26708984375","321.190002441406","5.98462764173746"
"8.16953368484974","635.719543457031","321.690002441406","5.98463555797935"
"8.1823393702507","180.131088256836","322.190002441406","5.98464580252767"
"8.19502584636211","116.20573425293","322.690002441406","5.98461274057627"
"8.19514505565166","115.468635559082","322.696990966797","5.98464347422123"